[2024-11-18T22:11:00.592+0000] {local_task_job_runner.py:123} INFO - ::group::Pre task execution logs
[2024-11-18T22:11:00.614+0000] {taskinstance.py:2613} INFO - Dependencies all met for dep_context=non-requeueable deps ti=<TaskInstance: load_customers_data_to_db.wait_for_dag_load_sales_data_to_db manual__2024-11-18T22:10:57.400038+00:00 [queued]>
[2024-11-18T22:11:00.624+0000] {taskinstance.py:2613} INFO - Dependencies all met for dep_context=requeueable deps ti=<TaskInstance: load_customers_data_to_db.wait_for_dag_load_sales_data_to_db manual__2024-11-18T22:10:57.400038+00:00 [queued]>
[2024-11-18T22:11:00.625+0000] {taskinstance.py:2866} INFO - Starting attempt 1 of 2
[2024-11-18T22:11:00.642+0000] {taskinstance.py:2889} INFO - Executing <Task(ExternalTaskSensor): wait_for_dag_load_sales_data_to_db> on 2024-11-18 22:10:57.400038+00:00
[2024-11-18T22:11:00.650+0000] {warnings.py:112} WARNING - /home/***/.local/lib/python3.12/site-packages/***/task/task_runner/standard_task_runner.py:70: DeprecationWarning: This process (pid=262) is multi-threaded, use of fork() may lead to deadlocks in the child.
  pid = os.fork()

[2024-11-18T22:11:00.652+0000] {standard_task_runner.py:72} INFO - Started process 264 to run task
[2024-11-18T22:11:00.653+0000] {standard_task_runner.py:104} INFO - Running: ['***', 'tasks', 'run', 'load_customers_data_to_db', 'wait_for_dag_load_sales_data_to_db', 'manual__2024-11-18T22:10:57.400038+00:00', '--job-id', '485', '--raw', '--subdir', 'DAGS_FOLDER/refined/insert_data_to_3.py', '--cfg-path', '/tmp/tmp9fskp__p']
[2024-11-18T22:11:00.655+0000] {standard_task_runner.py:105} INFO - Job 485: Subtask wait_for_dag_load_sales_data_to_db
[2024-11-18T22:11:00.718+0000] {task_command.py:467} INFO - Running <TaskInstance: load_customers_data_to_db.wait_for_dag_load_sales_data_to_db manual__2024-11-18T22:10:57.400038+00:00 [running]> on host c06adc74012b
[2024-11-18T22:11:00.840+0000] {taskinstance.py:3132} INFO - Exporting env vars: AIRFLOW_CTX_DAG_OWNER='***' AIRFLOW_CTX_DAG_ID='load_customers_data_to_db' AIRFLOW_CTX_TASK_ID='wait_for_dag_load_sales_data_to_db' AIRFLOW_CTX_EXECUTION_DATE='2024-11-18T22:10:57.400038+00:00' AIRFLOW_CTX_TRY_NUMBER='1' AIRFLOW_CTX_DAG_RUN_ID='manual__2024-11-18T22:10:57.400038+00:00'
[2024-11-18T22:11:00.842+0000] {logging_mixin.py:190} INFO - Task instance is in running state
[2024-11-18T22:11:00.843+0000] {logging_mixin.py:190} INFO -  Previous state of the Task instance: queued
[2024-11-18T22:11:00.844+0000] {logging_mixin.py:190} INFO - Current task name:wait_for_dag_load_sales_data_to_db state:running start_date:2024-11-18 22:11:00.615611+00:00
[2024-11-18T22:11:00.844+0000] {logging_mixin.py:190} INFO - Dag name:load_customers_data_to_db and current dag run status:running
[2024-11-18T22:11:00.845+0000] {taskinstance.py:731} INFO - ::endgroup::
[2024-11-18T22:11:00.846+0000] {baseoperator.py:416} WARNING - ExternalTaskSensor.execute cannot be called outside TaskInstance!
[2024-11-18T22:11:00.846+0000] {external_task.py:258} INFO - Poking for tasks ['insert_sales_data'] in dag raw_api_sales_data on 2024-11-18T22:10:57.400038+00:00 ... 
[2024-11-18T22:11:00.847+0000] {warnings.py:112} WARNING - /home/***/.local/lib/python3.12/site-packages/***/utils/session.py:97: DeprecationWarning: This method is deprecated and will be removed in future.
  return func(*args, session=session, **kwargs)

[2024-11-18T22:12:03.765+0000] {external_task.py:258} INFO - Poking for tasks ['insert_sales_data'] in dag raw_api_sales_data on 2024-11-18T22:10:57.400038+00:00 ... 
[2024-11-18T22:13:06.704+0000] {external_task.py:258} INFO - Poking for tasks ['insert_sales_data'] in dag raw_api_sales_data on 2024-11-18T22:10:57.400038+00:00 ... 
[2024-11-18T22:14:09.649+0000] {external_task.py:258} INFO - Poking for tasks ['insert_sales_data'] in dag raw_api_sales_data on 2024-11-18T22:10:57.400038+00:00 ... 
[2024-11-18T22:15:12.576+0000] {external_task.py:258} INFO - Poking for tasks ['insert_sales_data'] in dag raw_api_sales_data on 2024-11-18T22:10:57.400038+00:00 ... 
[2024-11-18T22:16:15.503+0000] {external_task.py:258} INFO - Poking for tasks ['insert_sales_data'] in dag raw_api_sales_data on 2024-11-18T22:10:57.400038+00:00 ... 
[2024-11-18T22:17:18.484+0000] {external_task.py:258} INFO - Poking for tasks ['insert_sales_data'] in dag raw_api_sales_data on 2024-11-18T22:10:57.400038+00:00 ... 
[2024-11-18T22:18:21.433+0000] {external_task.py:258} INFO - Poking for tasks ['insert_sales_data'] in dag raw_api_sales_data on 2024-11-18T22:10:57.400038+00:00 ... 
[2024-11-18T22:19:24.432+0000] {external_task.py:258} INFO - Poking for tasks ['insert_sales_data'] in dag raw_api_sales_data on 2024-11-18T22:10:57.400038+00:00 ... 
[2024-11-18T22:20:27.370+0000] {external_task.py:258} INFO - Poking for tasks ['insert_sales_data'] in dag raw_api_sales_data on 2024-11-18T22:10:57.400038+00:00 ... 
[2024-11-18T22:21:30.373+0000] {external_task.py:258} INFO - Poking for tasks ['insert_sales_data'] in dag raw_api_sales_data on 2024-11-18T22:10:57.400038+00:00 ... 
[2024-11-18T22:21:30.381+0000] {taskinstance.py:3311} ERROR - Task failed with exception
Traceback (most recent call last):
  File "/home/airflow/.local/lib/python3.12/site-packages/airflow/models/taskinstance.py", line 767, in _execute_task
    result = _execute_callable(context=context, **execute_callable_kwargs)
             ^^^^^^^^^^^^^^^^^^^^^^^^^^^^^^^^^^^^^^^^^^^^^^^^^^^^^^^^^^^^^
  File "/home/airflow/.local/lib/python3.12/site-packages/airflow/models/taskinstance.py", line 733, in _execute_callable
    return ExecutionCallableRunner(
           ^^^^^^^^^^^^^^^^^^^^^^^^
  File "/home/airflow/.local/lib/python3.12/site-packages/airflow/utils/operator_helpers.py", line 252, in run
    return self.func(*args, **kwargs)
           ^^^^^^^^^^^^^^^^^^^^^^^^^^
  File "/home/airflow/.local/lib/python3.12/site-packages/airflow/models/baseoperator.py", line 417, in wrapper
    return func(self, *args, **kwargs)
           ^^^^^^^^^^^^^^^^^^^^^^^^^^^
  File "/home/airflow/.local/lib/python3.12/site-packages/airflow/sensors/external_task.py", line 348, in execute
    super().execute(context)
  File "/home/airflow/.local/lib/python3.12/site-packages/airflow/models/baseoperator.py", line 417, in wrapper
    return func(self, *args, **kwargs)
           ^^^^^^^^^^^^^^^^^^^^^^^^^^^
  File "/home/airflow/.local/lib/python3.12/site-packages/airflow/sensors/base.py", line 323, in execute
    raise AirflowSensorTimeout(message)
airflow.exceptions.AirflowSensorTimeout: Sensor has timed out; run duration of 600.1696912350017 seconds exceeds the specified timeout of 600.0.
[2024-11-18T22:21:30.390+0000] {logging_mixin.py:190} INFO - Task instance in failure state
[2024-11-18T22:21:30.391+0000] {logging_mixin.py:190} INFO - Task start:2024-11-18 22:11:00.615611+00:00 end:2024-11-18 22:21:30.390330+00:00 duration:629.774719
[2024-11-18T22:21:30.392+0000] {logging_mixin.py:190} INFO - Task:<Task(ExternalTaskSensor): wait_for_dag_load_sales_data_to_db> dag:<DAG: load_customers_data_to_db> dagrun:<DagRun load_customers_data_to_db @ 2024-11-18 22:10:57.400038+00:00: manual__2024-11-18T22:10:57.400038+00:00, state:running, queued_at: 2024-11-18 22:10:57.421203+00:00. externally triggered: True>
[2024-11-18T22:21:30.392+0000] {logging_mixin.py:190} INFO - Failure caused by Sensor has timed out; run duration of 600.1696912350017 seconds exceeds the specified timeout of 600.0.
[2024-11-18T22:21:30.393+0000] {taskinstance.py:1225} INFO - Immediate failure requested. Marking task as FAILED. dag_id=load_customers_data_to_db, task_id=wait_for_dag_load_sales_data_to_db, run_id=manual__2024-11-18T22:10:57.400038+00:00, execution_date=20241118T221057, start_date=20241118T221100, end_date=20241118T222130
[2024-11-18T22:21:30.410+0000] {taskinstance.py:340} INFO - ::group::Post task execution logs
[2024-11-18T22:21:30.411+0000] {standard_task_runner.py:124} ERROR - Failed to execute job 485 for task wait_for_dag_load_sales_data_to_db (Sensor has timed out; run duration of 600.1696912350017 seconds exceeds the specified timeout of 600.0.; 264)
Traceback (most recent call last):
  File "/home/airflow/.local/lib/python3.12/site-packages/airflow/task/task_runner/standard_task_runner.py", line 117, in _start_by_fork
    ret = args.func(args, dag=self.dag)
          ^^^^^^^^^^^^^^^^^^^^^^^^^^^^^
  File "/home/airflow/.local/lib/python3.12/site-packages/airflow/cli/cli_config.py", line 49, in command
    return func(*args, **kwargs)
           ^^^^^^^^^^^^^^^^^^^^^
  File "/home/airflow/.local/lib/python3.12/site-packages/airflow/utils/cli.py", line 116, in wrapper
    return f(*args, **kwargs)
           ^^^^^^^^^^^^^^^^^^
  File "/home/airflow/.local/lib/python3.12/site-packages/airflow/cli/commands/task_command.py", line 483, in task_run
    task_return_code = _run_task_by_selected_method(args, _dag, ti)
                       ^^^^^^^^^^^^^^^^^^^^^^^^^^^^^^^^^^^^^^^^^^^^
  File "/home/airflow/.local/lib/python3.12/site-packages/airflow/cli/commands/task_command.py", line 256, in _run_task_by_selected_method
    return _run_raw_task(args, ti)
           ^^^^^^^^^^^^^^^^^^^^^^^
  File "/home/airflow/.local/lib/python3.12/site-packages/airflow/cli/commands/task_command.py", line 341, in _run_raw_task
    return ti._run_raw_task(
           ^^^^^^^^^^^^^^^^^
  File "/home/airflow/.local/lib/python3.12/site-packages/airflow/utils/session.py", line 97, in wrapper
    return func(*args, session=session, **kwargs)
           ^^^^^^^^^^^^^^^^^^^^^^^^^^^^^^^^^^^^^^
  File "/home/airflow/.local/lib/python3.12/site-packages/airflow/models/taskinstance.py", line 3005, in _run_raw_task
    return _run_raw_task(
           ^^^^^^^^^^^^^^
  File "/home/airflow/.local/lib/python3.12/site-packages/airflow/models/taskinstance.py", line 273, in _run_raw_task
    TaskInstance._execute_task_with_callbacks(
  File "/home/airflow/.local/lib/python3.12/site-packages/airflow/models/taskinstance.py", line 3159, in _execute_task_with_callbacks
    result = self._execute_task(context, task_orig)
             ^^^^^^^^^^^^^^^^^^^^^^^^^^^^^^^^^^^^^^
  File "/home/airflow/.local/lib/python3.12/site-packages/airflow/models/taskinstance.py", line 3183, in _execute_task
    return _execute_task(self, context, task_orig)
           ^^^^^^^^^^^^^^^^^^^^^^^^^^^^^^^^^^^^^^^
  File "/home/airflow/.local/lib/python3.12/site-packages/airflow/models/taskinstance.py", line 767, in _execute_task
    result = _execute_callable(context=context, **execute_callable_kwargs)
             ^^^^^^^^^^^^^^^^^^^^^^^^^^^^^^^^^^^^^^^^^^^^^^^^^^^^^^^^^^^^^
  File "/home/airflow/.local/lib/python3.12/site-packages/airflow/models/taskinstance.py", line 733, in _execute_callable
    return ExecutionCallableRunner(
           ^^^^^^^^^^^^^^^^^^^^^^^^
  File "/home/airflow/.local/lib/python3.12/site-packages/airflow/utils/operator_helpers.py", line 252, in run
    return self.func(*args, **kwargs)
           ^^^^^^^^^^^^^^^^^^^^^^^^^^
  File "/home/airflow/.local/lib/python3.12/site-packages/airflow/models/baseoperator.py", line 417, in wrapper
    return func(self, *args, **kwargs)
           ^^^^^^^^^^^^^^^^^^^^^^^^^^^
  File "/home/airflow/.local/lib/python3.12/site-packages/airflow/sensors/external_task.py", line 348, in execute
    super().execute(context)
  File "/home/airflow/.local/lib/python3.12/site-packages/airflow/models/baseoperator.py", line 417, in wrapper
    return func(self, *args, **kwargs)
           ^^^^^^^^^^^^^^^^^^^^^^^^^^^
  File "/home/airflow/.local/lib/python3.12/site-packages/airflow/sensors/base.py", line 323, in execute
    raise AirflowSensorTimeout(message)
airflow.exceptions.AirflowSensorTimeout: Sensor has timed out; run duration of 600.1696912350017 seconds exceeds the specified timeout of 600.0.
[2024-11-18T22:21:30.443+0000] {local_task_job_runner.py:266} INFO - Task exited with return code 1
[2024-11-18T22:21:30.458+0000] {taskinstance.py:3895} INFO - 0 downstream tasks scheduled from follow-on schedule check
[2024-11-18T22:21:30.460+0000] {local_task_job_runner.py:245} INFO - ::endgroup::
