[2024-11-17T22:10:20.859+0000] {local_task_job_runner.py:123} INFO - ::group::Pre task execution logs
[2024-11-17T22:10:21.097+0000] {taskinstance.py:2613} INFO - Dependencies all met for dep_context=non-requeueable deps ti=<TaskInstance: raw_api_sales_data.insert_sales_data scheduled__2024-11-17T22:00:00+00:00 [queued]>
[2024-11-17T22:10:21.110+0000] {taskinstance.py:2613} INFO - Dependencies all met for dep_context=requeueable deps ti=<TaskInstance: raw_api_sales_data.insert_sales_data scheduled__2024-11-17T22:00:00+00:00 [queued]>
[2024-11-17T22:10:21.111+0000] {taskinstance.py:2866} INFO - Starting attempt 2 of 2
[2024-11-17T22:10:21.134+0000] {taskinstance.py:2889} INFO - Executing <Task(PythonOperator): insert_sales_data> on 2024-11-17 22:00:00+00:00
[2024-11-17T22:10:21.144+0000] {warnings.py:112} WARNING - /home/***/.local/lib/python3.12/site-packages/***/task/task_runner/standard_task_runner.py:70: DeprecationWarning: This process (pid=229) is multi-threaded, use of fork() may lead to deadlocks in the child.
  pid = os.fork()

[2024-11-17T22:10:21.148+0000] {standard_task_runner.py:72} INFO - Started process 231 to run task
[2024-11-17T22:10:21.149+0000] {standard_task_runner.py:104} INFO - Running: ['***', 'tasks', 'run', 'raw_api_sales_data', 'insert_sales_data', 'scheduled__2024-11-17T22:00:00+00:00', '--job-id', '117', '--raw', '--subdir', 'DAGS_FOLDER/fetch_data.py', '--cfg-path', '/tmp/tmpik6239zm']
[2024-11-17T22:10:21.152+0000] {standard_task_runner.py:105} INFO - Job 117: Subtask insert_sales_data
[2024-11-17T22:10:21.297+0000] {task_command.py:467} INFO - Running <TaskInstance: raw_api_sales_data.insert_sales_data scheduled__2024-11-17T22:00:00+00:00 [running]> on host 525767e32e17
[2024-11-17T22:10:21.525+0000] {taskinstance.py:3132} INFO - Exporting env vars: AIRFLOW_CTX_DAG_OWNER='***' AIRFLOW_CTX_DAG_ID='raw_api_sales_data' AIRFLOW_CTX_TASK_ID='insert_sales_data' AIRFLOW_CTX_EXECUTION_DATE='2024-11-17T22:00:00+00:00' AIRFLOW_CTX_TRY_NUMBER='2' AIRFLOW_CTX_DAG_RUN_ID='scheduled__2024-11-17T22:00:00+00:00'
[2024-11-17T22:10:21.529+0000] {logging_mixin.py:190} INFO - Task instance is in running state
[2024-11-17T22:10:21.530+0000] {logging_mixin.py:190} INFO -  Previous state of the Task instance: queued
[2024-11-17T22:10:21.531+0000] {logging_mixin.py:190} INFO - Current task name:insert_sales_data state:running start_date:2024-11-17 22:10:21.098395+00:00
[2024-11-17T22:10:21.532+0000] {logging_mixin.py:190} INFO - Dag name:raw_api_sales_data and current dag run status:running
[2024-11-17T22:10:21.534+0000] {taskinstance.py:731} INFO - ::endgroup::
[2024-11-17T22:10:21.536+0000] {logging_mixin.py:190} INFO - ti: <TaskInstance: raw_api_sales_data.insert_sales_data scheduled__2024-11-17T22:00:00+00:00 [running]>
[2024-11-17T22:10:21.561+0000] {logging_mixin.py:190} INFO - sales_data: [{'customer_id': 382, 'customer_name': 'Fredi Izard', 'age': 26, 'email': 'fizard0@t.co', 'country': 'Indonesia', 'postal_code': nan, 'purchase_id': 1906, 'purchase_quantity': 12, 'purchase_date': '9/20/2021', 'product_id': 2036, 'product_name': 'Cheese - Stilton', 'quantity': 531, 'total_price': 2467.74, 'price_unit': 274.9}, {'customer_id': 553, 'customer_name': 'Paulette Edgcumbe', 'age': 36, 'email': 'pedgcumbe1@shop-pro.jp', 'country': 'China', 'postal_code': nan, 'purchase_id': 1628, 'purchase_quantity': 74, 'purchase_date': '2/8/2021', 'product_id': 2031, 'product_name': 'Table Cloth 72x144 White', 'quantity': 662, 'total_price': 7760.88, 'price_unit': 999.02}, {'customer_id': 169, 'customer_name': 'Hernando Goff', 'age': 36, 'email': 'hgoff2@ning.com', 'country': 'Indonesia', 'postal_code': nan, 'purchase_id': 298, 'purchase_quantity': 11, 'purchase_date': '12/20/2021', 'product_id': 2082, 'product_name': 'Crackers - Water', 'quantity': 444, 'total_price': 9240.76, 'price_unit': 633.02}, {'customer_id': 557, 'customer_name': 'Craggie Saltman', 'age': 69, 'email': 'csaltman3@businessinsider.com', 'country': 'Philippines', 'postal_code': '5608', 'purchase_id': 450, 'purchase_quantity': 6, 'purchase_date': '9/1/2021', 'product_id': 2058, 'product_name': 'Jameson - Irish Whiskey', 'quantity': 181, 'total_price': 3146.02, 'price_unit': 687.69}, {'customer_id': 910, 'customer_name': 'Del Gantzer', 'age': 66, 'email': 'dgantzer4@cdbaby.com', 'country': 'Russia', 'postal_code': '456922', 'purchase_id': 1276, 'purchase_quantity': 92, 'purchase_date': '3/30/2021', 'product_id': 2083, 'product_name': 'Wine - White Cab Sauv.on', 'quantity': 858, 'total_price': 4979.45, 'price_unit': 587.35}, {'customer_id': 663, 'customer_name': 'Shoshanna Brandsen', 'age': 75, 'email': 'sbrandsen5@people.com.cn', 'country': 'Argentina', 'postal_code': '6070', 'purchase_id': 710, 'purchase_quantity': 100, 'purchase_date': '2/17/2021', 'product_id': 2045, 'product_name': 'Beans - Wax', 'quantity': 674, 'total_price': 4420.39, 'price_unit': 619.44}, {'customer_id': 127, 'customer_name': 'Sioux Desantis', 'age': 28, 'email': 'sdesantis6@so-net.ne.jp', 'country': 'Canada', 'postal_code': 'L7E', 'purchase_id': 1145, 'purchase_quantity': 48, 'purchase_date': '5/26/2021', 'product_id': 2081, 'product_name': 'Flower - Commercial Spider', 'quantity': 148, 'total_price': 7305.6, 'price_unit': 344.92}, {'customer_id': 315, 'customer_name': 'Glendon Argyle', 'age': 82, 'email': 'gargyle7@w3.org', 'country': 'Iran', 'postal_code': nan, 'purchase_id': 938, 'purchase_quantity': 60, 'purchase_date': '5/1/2021', 'product_id': 2014, 'product_name': 'Beer - Sleeman Fine Porter', 'quantity': 901, 'total_price': 9610.18, 'price_unit': 601.47}, {'customer_id': 345, 'customer_name': 'Claudetta Cambell', 'age': 67, 'email': 'ccambell8@berkeley.edu', 'country': 'France', 'postal_code': '16919 CEDEX 9', 'purchase_id': 1402, 'purchase_quantity': 96, 'purchase_date': '4/26/2021', 'product_id': 2070, 'product_name': 'Pear - Asian', 'quantity': 404, 'total_price': 606.53, 'price_unit': 863.14}, {'customer_id': 634, 'customer_name': 'Lamar MacFie', 'age': 25, 'email': 'lmacfie9@xrea.com', 'country': 'Sweden', 'postal_code': '133 41', 'purchase_id': 1712, 'purchase_quantity': 55, 'purchase_date': '3/14/2021', 'product_id': 2069, 'product_name': 'Lumpfish Black', 'quantity': 324, 'total_price': 4307.77, 'price_unit': 219.58}]
[2024-11-17T22:10:21.583+0000] {base.py:84} INFO - Retrieving connection 'postgres_default'
[2024-11-17T22:10:21.587+0000] {taskinstance.py:3311} ERROR - Task failed with exception
Traceback (most recent call last):
  File "/home/airflow/.local/lib/python3.12/site-packages/airflow/models/taskinstance.py", line 767, in _execute_task
    result = _execute_callable(context=context, **execute_callable_kwargs)
             ^^^^^^^^^^^^^^^^^^^^^^^^^^^^^^^^^^^^^^^^^^^^^^^^^^^^^^^^^^^^^
  File "/home/airflow/.local/lib/python3.12/site-packages/airflow/models/taskinstance.py", line 733, in _execute_callable
    return ExecutionCallableRunner(
           ^^^^^^^^^^^^^^^^^^^^^^^^
  File "/home/airflow/.local/lib/python3.12/site-packages/airflow/utils/operator_helpers.py", line 252, in run
    return self.func(*args, **kwargs)
           ^^^^^^^^^^^^^^^^^^^^^^^^^^
  File "/home/airflow/.local/lib/python3.12/site-packages/airflow/models/baseoperator.py", line 417, in wrapper
    return func(self, *args, **kwargs)
           ^^^^^^^^^^^^^^^^^^^^^^^^^^^
  File "/home/airflow/.local/lib/python3.12/site-packages/airflow/operators/python.py", line 238, in execute
    return_value = self.execute_callable()
                   ^^^^^^^^^^^^^^^^^^^^^^^
  File "/home/airflow/.local/lib/python3.12/site-packages/airflow/operators/python.py", line 256, in execute_callable
    return runner.run(*self.op_args, **self.op_kwargs)
           ^^^^^^^^^^^^^^^^^^^^^^^^^^^^^^^^^^^^^^^^^^^
  File "/home/airflow/.local/lib/python3.12/site-packages/airflow/utils/operator_helpers.py", line 252, in run
    return self.func(*args, **kwargs)
           ^^^^^^^^^^^^^^^^^^^^^^^^^^
  File "/opt/airflow/dags/fetch_data.py", line 59, in insert_sales_data
    conn = hook.get_conn()
           ^^^^^^^^^^^^^^^
  File "/home/airflow/.local/lib/python3.12/site-packages/airflow/providers/postgres/hooks/postgres.py", line 181, in get_conn
    self.conn = psycopg2.connect(**conn_args)
                ^^^^^^^^^^^^^^^^^^^^^^^^^^^^^
  File "/home/airflow/.local/lib/python3.12/site-packages/psycopg2/__init__.py", line 122, in connect
    conn = _connect(dsn, connection_factory=connection_factory, **kwasync)
           ^^^^^^^^^^^^^^^^^^^^^^^^^^^^^^^^^^^^^^^^^^^^^^^^^^^^^^^^^^^^^^^
psycopg2.OperationalError: connection to server at "localhost" (::1), port 5432 failed: Connection refused
	Is the server running on that host and accepting TCP/IP connections?
connection to server at "localhost" (127.0.0.1), port 5432 failed: Connection refused
	Is the server running on that host and accepting TCP/IP connections?

[2024-11-17T22:10:21.620+0000] {logging_mixin.py:190} INFO - Task instance in failure state
[2024-11-17T22:10:21.621+0000] {logging_mixin.py:190} INFO - Task start:2024-11-17 22:10:21.098395+00:00 end:2024-11-17 22:10:21.619230+00:00 duration:0.520835
[2024-11-17T22:10:21.623+0000] {logging_mixin.py:190} INFO - Task:<Task(PythonOperator): insert_sales_data> dag:<DAG: raw_api_sales_data> dagrun:<DagRun raw_api_sales_data @ 2024-11-17 22:00:00+00:00: scheduled__2024-11-17T22:00:00+00:00, state:running, queued_at: 2024-11-17 22:10:00.187915+00:00. externally triggered: False>
[2024-11-17T22:10:21.624+0000] {logging_mixin.py:190} INFO - Failure caused by connection to server at "localhost" (::1), port 5432 failed: Connection refused
	Is the server running on that host and accepting TCP/IP connections?
connection to server at "localhost" (127.0.0.1), port 5432 failed: Connection refused
	Is the server running on that host and accepting TCP/IP connections?
[2024-11-17T22:10:21.625+0000] {taskinstance.py:1225} INFO - Marking task as FAILED. dag_id=raw_api_sales_data, task_id=insert_sales_data, run_id=scheduled__2024-11-17T22:00:00+00:00, execution_date=20241117T220000, start_date=20241117T221021, end_date=20241117T221021
[2024-11-17T22:10:21.654+0000] {taskinstance.py:340} INFO - ::group::Post task execution logs
[2024-11-17T22:10:21.656+0000] {standard_task_runner.py:124} ERROR - Failed to execute job 117 for task insert_sales_data (connection to server at "localhost" (::1), port 5432 failed: Connection refused
	Is the server running on that host and accepting TCP/IP connections?
connection to server at "localhost" (127.0.0.1), port 5432 failed: Connection refused
	Is the server running on that host and accepting TCP/IP connections?
; 231)
Traceback (most recent call last):
  File "/home/airflow/.local/lib/python3.12/site-packages/airflow/task/task_runner/standard_task_runner.py", line 117, in _start_by_fork
    ret = args.func(args, dag=self.dag)
          ^^^^^^^^^^^^^^^^^^^^^^^^^^^^^
  File "/home/airflow/.local/lib/python3.12/site-packages/airflow/cli/cli_config.py", line 49, in command
    return func(*args, **kwargs)
           ^^^^^^^^^^^^^^^^^^^^^
  File "/home/airflow/.local/lib/python3.12/site-packages/airflow/utils/cli.py", line 116, in wrapper
    return f(*args, **kwargs)
           ^^^^^^^^^^^^^^^^^^
  File "/home/airflow/.local/lib/python3.12/site-packages/airflow/cli/commands/task_command.py", line 483, in task_run
    task_return_code = _run_task_by_selected_method(args, _dag, ti)
                       ^^^^^^^^^^^^^^^^^^^^^^^^^^^^^^^^^^^^^^^^^^^^
  File "/home/airflow/.local/lib/python3.12/site-packages/airflow/cli/commands/task_command.py", line 256, in _run_task_by_selected_method
    return _run_raw_task(args, ti)
           ^^^^^^^^^^^^^^^^^^^^^^^
  File "/home/airflow/.local/lib/python3.12/site-packages/airflow/cli/commands/task_command.py", line 341, in _run_raw_task
    return ti._run_raw_task(
           ^^^^^^^^^^^^^^^^^
  File "/home/airflow/.local/lib/python3.12/site-packages/airflow/utils/session.py", line 97, in wrapper
    return func(*args, session=session, **kwargs)
           ^^^^^^^^^^^^^^^^^^^^^^^^^^^^^^^^^^^^^^
  File "/home/airflow/.local/lib/python3.12/site-packages/airflow/models/taskinstance.py", line 3005, in _run_raw_task
    return _run_raw_task(
           ^^^^^^^^^^^^^^
  File "/home/airflow/.local/lib/python3.12/site-packages/airflow/models/taskinstance.py", line 273, in _run_raw_task
    TaskInstance._execute_task_with_callbacks(
  File "/home/airflow/.local/lib/python3.12/site-packages/airflow/models/taskinstance.py", line 3159, in _execute_task_with_callbacks
    result = self._execute_task(context, task_orig)
             ^^^^^^^^^^^^^^^^^^^^^^^^^^^^^^^^^^^^^^
  File "/home/airflow/.local/lib/python3.12/site-packages/airflow/models/taskinstance.py", line 3183, in _execute_task
    return _execute_task(self, context, task_orig)
           ^^^^^^^^^^^^^^^^^^^^^^^^^^^^^^^^^^^^^^^
  File "/home/airflow/.local/lib/python3.12/site-packages/airflow/models/taskinstance.py", line 767, in _execute_task
    result = _execute_callable(context=context, **execute_callable_kwargs)
             ^^^^^^^^^^^^^^^^^^^^^^^^^^^^^^^^^^^^^^^^^^^^^^^^^^^^^^^^^^^^^
  File "/home/airflow/.local/lib/python3.12/site-packages/airflow/models/taskinstance.py", line 733, in _execute_callable
    return ExecutionCallableRunner(
           ^^^^^^^^^^^^^^^^^^^^^^^^
  File "/home/airflow/.local/lib/python3.12/site-packages/airflow/utils/operator_helpers.py", line 252, in run
    return self.func(*args, **kwargs)
           ^^^^^^^^^^^^^^^^^^^^^^^^^^
  File "/home/airflow/.local/lib/python3.12/site-packages/airflow/models/baseoperator.py", line 417, in wrapper
    return func(self, *args, **kwargs)
           ^^^^^^^^^^^^^^^^^^^^^^^^^^^
  File "/home/airflow/.local/lib/python3.12/site-packages/airflow/operators/python.py", line 238, in execute
    return_value = self.execute_callable()
                   ^^^^^^^^^^^^^^^^^^^^^^^
  File "/home/airflow/.local/lib/python3.12/site-packages/airflow/operators/python.py", line 256, in execute_callable
    return runner.run(*self.op_args, **self.op_kwargs)
           ^^^^^^^^^^^^^^^^^^^^^^^^^^^^^^^^^^^^^^^^^^^
  File "/home/airflow/.local/lib/python3.12/site-packages/airflow/utils/operator_helpers.py", line 252, in run
    return self.func(*args, **kwargs)
           ^^^^^^^^^^^^^^^^^^^^^^^^^^
  File "/opt/airflow/dags/fetch_data.py", line 59, in insert_sales_data
    conn = hook.get_conn()
           ^^^^^^^^^^^^^^^
  File "/home/airflow/.local/lib/python3.12/site-packages/airflow/providers/postgres/hooks/postgres.py", line 181, in get_conn
    self.conn = psycopg2.connect(**conn_args)
                ^^^^^^^^^^^^^^^^^^^^^^^^^^^^^
  File "/home/airflow/.local/lib/python3.12/site-packages/psycopg2/__init__.py", line 122, in connect
    conn = _connect(dsn, connection_factory=connection_factory, **kwasync)
           ^^^^^^^^^^^^^^^^^^^^^^^^^^^^^^^^^^^^^^^^^^^^^^^^^^^^^^^^^^^^^^^
psycopg2.OperationalError: connection to server at "localhost" (::1), port 5432 failed: Connection refused
	Is the server running on that host and accepting TCP/IP connections?
connection to server at "localhost" (127.0.0.1), port 5432 failed: Connection refused
	Is the server running on that host and accepting TCP/IP connections?

[2024-11-17T22:10:21.687+0000] {local_task_job_runner.py:266} INFO - Task exited with return code 1
[2024-11-17T22:10:21.737+0000] {taskinstance.py:3895} INFO - 0 downstream tasks scheduled from follow-on schedule check
[2024-11-17T22:10:21.742+0000] {local_task_job_runner.py:245} INFO - ::endgroup::
