[2024-11-18T22:41:04.450+0000] {local_task_job_runner.py:123} INFO - ::group::Pre task execution logs
[2024-11-18T22:41:04.512+0000] {taskinstance.py:2613} INFO - Dependencies all met for dep_context=non-requeueable deps ti=<TaskInstance: load_customers_data_to_db.transform_data manual__2024-11-18T22:40:55.961566+00:00 [queued]>
[2024-11-18T22:41:04.543+0000] {taskinstance.py:2613} INFO - Dependencies all met for dep_context=requeueable deps ti=<TaskInstance: load_customers_data_to_db.transform_data manual__2024-11-18T22:40:55.961566+00:00 [queued]>
[2024-11-18T22:41:04.545+0000] {taskinstance.py:2866} INFO - Starting attempt 1 of 2
[2024-11-18T22:41:04.590+0000] {taskinstance.py:2889} INFO - Executing <Task(PythonOperator): transform_data> on 2024-11-18 22:40:55.961566+00:00
[2024-11-18T22:41:04.605+0000] {warnings.py:112} WARNING - /home/***/.local/lib/python3.12/site-packages/***/task/task_runner/standard_task_runner.py:70: DeprecationWarning: This process (pid=180) is multi-threaded, use of fork() may lead to deadlocks in the child.
  pid = os.fork()

[2024-11-18T22:41:04.609+0000] {standard_task_runner.py:72} INFO - Started process 186 to run task
[2024-11-18T22:41:04.620+0000] {standard_task_runner.py:104} INFO - Running: ['***', 'tasks', 'run', 'load_customers_data_to_db', 'transform_data', 'manual__2024-11-18T22:40:55.961566+00:00', '--job-id', '524', '--raw', '--subdir', 'DAGS_FOLDER/refined/insert_data_to_3.py', '--cfg-path', '/tmp/tmpkqf_cm6a']
[2024-11-18T22:41:04.624+0000] {standard_task_runner.py:105} INFO - Job 524: Subtask transform_data
[2024-11-18T22:41:04.777+0000] {task_command.py:467} INFO - Running <TaskInstance: load_customers_data_to_db.transform_data manual__2024-11-18T22:40:55.961566+00:00 [running]> on host c06adc74012b
[2024-11-18T22:41:05.047+0000] {taskinstance.py:3132} INFO - Exporting env vars: AIRFLOW_CTX_DAG_OWNER='***' AIRFLOW_CTX_DAG_ID='load_customers_data_to_db' AIRFLOW_CTX_TASK_ID='transform_data' AIRFLOW_CTX_EXECUTION_DATE='2024-11-18T22:40:55.961566+00:00' AIRFLOW_CTX_TRY_NUMBER='1' AIRFLOW_CTX_DAG_RUN_ID='manual__2024-11-18T22:40:55.961566+00:00'
[2024-11-18T22:41:05.051+0000] {logging_mixin.py:190} INFO - Task instance is in running state
[2024-11-18T22:41:05.052+0000] {logging_mixin.py:190} INFO -  Previous state of the Task instance: queued
[2024-11-18T22:41:05.054+0000] {logging_mixin.py:190} INFO - Current task name:transform_data state:running start_date:2024-11-18 22:41:04.515322+00:00
[2024-11-18T22:41:05.055+0000] {logging_mixin.py:190} INFO - Dag name:load_customers_data_to_db and current dag run status:running
[2024-11-18T22:41:05.058+0000] {taskinstance.py:731} INFO - ::endgroup::
[2024-11-18T22:41:05.083+0000] {base.py:84} INFO - Retrieving connection 'postgres_default'
[2024-11-18T22:41:05.117+0000] {insert_data_to_3.py:28} INFO - Nombre de lignes récupérées : 70
[2024-11-18T22:41:05.118+0000] {insert_data_to_3.py:32} INFO - Traitement de la ligne : (722, 'Keven Luciano', 20, 'kluciano0@dagondesign.com', 'Nigeria', 'NaN', 1298, 83, datetime.date(2021, 4, 16), 2058, 'Basil - Pesto Sauce', 412, Decimal('706.03'))
[2024-11-18T22:41:05.130+0000] {insert_data_to_3.py:63} ERROR - Erreur lors de l'insertion des données : insert or update on table "command" violates foreign key constraint "command_product_id_fkey"
DETAIL:  Key (product_id)=(2058) is not present in table "product".

[2024-11-18T22:41:05.134+0000] {taskinstance.py:3311} ERROR - Task failed with exception
Traceback (most recent call last):
  File "/home/airflow/.local/lib/python3.12/site-packages/airflow/models/taskinstance.py", line 767, in _execute_task
    result = _execute_callable(context=context, **execute_callable_kwargs)
             ^^^^^^^^^^^^^^^^^^^^^^^^^^^^^^^^^^^^^^^^^^^^^^^^^^^^^^^^^^^^^
  File "/home/airflow/.local/lib/python3.12/site-packages/airflow/models/taskinstance.py", line 733, in _execute_callable
    return ExecutionCallableRunner(
           ^^^^^^^^^^^^^^^^^^^^^^^^
  File "/home/airflow/.local/lib/python3.12/site-packages/airflow/utils/operator_helpers.py", line 252, in run
    return self.func(*args, **kwargs)
           ^^^^^^^^^^^^^^^^^^^^^^^^^^
  File "/home/airflow/.local/lib/python3.12/site-packages/airflow/models/baseoperator.py", line 417, in wrapper
    return func(self, *args, **kwargs)
           ^^^^^^^^^^^^^^^^^^^^^^^^^^^
  File "/home/airflow/.local/lib/python3.12/site-packages/airflow/operators/python.py", line 238, in execute
    return_value = self.execute_callable()
                   ^^^^^^^^^^^^^^^^^^^^^^^
  File "/home/airflow/.local/lib/python3.12/site-packages/airflow/operators/python.py", line 256, in execute_callable
    return runner.run(*self.op_args, **self.op_kwargs)
           ^^^^^^^^^^^^^^^^^^^^^^^^^^^^^^^^^^^^^^^^^^^
  File "/home/airflow/.local/lib/python3.12/site-packages/airflow/utils/operator_helpers.py", line 252, in run
    return self.func(*args, **kwargs)
           ^^^^^^^^^^^^^^^^^^^^^^^^^^
  File "/opt/airflow/dags/refined/insert_data_to_3.py", line 43, in transform_data
    cursor.execute("""
psycopg2.errors.ForeignKeyViolation: insert or update on table "command" violates foreign key constraint "command_product_id_fkey"
DETAIL:  Key (product_id)=(2058) is not present in table "product".

[2024-11-18T22:41:05.176+0000] {logging_mixin.py:190} INFO - Task instance in failure state
[2024-11-18T22:41:05.177+0000] {logging_mixin.py:190} INFO - Task start:2024-11-18 22:41:04.515322+00:00 end:2024-11-18 22:41:05.175260+00:00 duration:0.659938
[2024-11-18T22:41:05.177+0000] {logging_mixin.py:190} INFO - Task:<Task(PythonOperator): transform_data> dag:<DAG: load_customers_data_to_db> dagrun:<DagRun load_customers_data_to_db @ 2024-11-18 22:40:55.961566+00:00: manual__2024-11-18T22:40:55.961566+00:00, state:running, queued_at: 2024-11-18 22:40:55.986996+00:00. externally triggered: True>
[2024-11-18T22:41:05.178+0000] {logging_mixin.py:190} INFO - Failure caused by insert or update on table "command" violates foreign key constraint "command_product_id_fkey"
DETAIL:  Key (product_id)=(2058) is not present in table "product".
[2024-11-18T22:41:05.179+0000] {taskinstance.py:1225} INFO - Marking task as UP_FOR_RETRY. dag_id=load_customers_data_to_db, task_id=transform_data, run_id=manual__2024-11-18T22:40:55.961566+00:00, execution_date=20241118T224055, start_date=20241118T224104, end_date=20241118T224105
[2024-11-18T22:41:05.219+0000] {taskinstance.py:340} INFO - ::group::Post task execution logs
[2024-11-18T22:41:05.221+0000] {standard_task_runner.py:124} ERROR - Failed to execute job 524 for task transform_data (insert or update on table "command" violates foreign key constraint "command_product_id_fkey"
DETAIL:  Key (product_id)=(2058) is not present in table "product".
; 186)
Traceback (most recent call last):
  File "/home/airflow/.local/lib/python3.12/site-packages/airflow/task/task_runner/standard_task_runner.py", line 117, in _start_by_fork
    ret = args.func(args, dag=self.dag)
          ^^^^^^^^^^^^^^^^^^^^^^^^^^^^^
  File "/home/airflow/.local/lib/python3.12/site-packages/airflow/cli/cli_config.py", line 49, in command
    return func(*args, **kwargs)
           ^^^^^^^^^^^^^^^^^^^^^
  File "/home/airflow/.local/lib/python3.12/site-packages/airflow/utils/cli.py", line 116, in wrapper
    return f(*args, **kwargs)
           ^^^^^^^^^^^^^^^^^^
  File "/home/airflow/.local/lib/python3.12/site-packages/airflow/cli/commands/task_command.py", line 483, in task_run
    task_return_code = _run_task_by_selected_method(args, _dag, ti)
                       ^^^^^^^^^^^^^^^^^^^^^^^^^^^^^^^^^^^^^^^^^^^^
  File "/home/airflow/.local/lib/python3.12/site-packages/airflow/cli/commands/task_command.py", line 256, in _run_task_by_selected_method
    return _run_raw_task(args, ti)
           ^^^^^^^^^^^^^^^^^^^^^^^
  File "/home/airflow/.local/lib/python3.12/site-packages/airflow/cli/commands/task_command.py", line 341, in _run_raw_task
    return ti._run_raw_task(
           ^^^^^^^^^^^^^^^^^
  File "/home/airflow/.local/lib/python3.12/site-packages/airflow/utils/session.py", line 97, in wrapper
    return func(*args, session=session, **kwargs)
           ^^^^^^^^^^^^^^^^^^^^^^^^^^^^^^^^^^^^^^
  File "/home/airflow/.local/lib/python3.12/site-packages/airflow/models/taskinstance.py", line 3005, in _run_raw_task
    return _run_raw_task(
           ^^^^^^^^^^^^^^
  File "/home/airflow/.local/lib/python3.12/site-packages/airflow/models/taskinstance.py", line 273, in _run_raw_task
    TaskInstance._execute_task_with_callbacks(
  File "/home/airflow/.local/lib/python3.12/site-packages/airflow/models/taskinstance.py", line 3159, in _execute_task_with_callbacks
    result = self._execute_task(context, task_orig)
             ^^^^^^^^^^^^^^^^^^^^^^^^^^^^^^^^^^^^^^
  File "/home/airflow/.local/lib/python3.12/site-packages/airflow/models/taskinstance.py", line 3183, in _execute_task
    return _execute_task(self, context, task_orig)
           ^^^^^^^^^^^^^^^^^^^^^^^^^^^^^^^^^^^^^^^
  File "/home/airflow/.local/lib/python3.12/site-packages/airflow/models/taskinstance.py", line 767, in _execute_task
    result = _execute_callable(context=context, **execute_callable_kwargs)
             ^^^^^^^^^^^^^^^^^^^^^^^^^^^^^^^^^^^^^^^^^^^^^^^^^^^^^^^^^^^^^
  File "/home/airflow/.local/lib/python3.12/site-packages/airflow/models/taskinstance.py", line 733, in _execute_callable
    return ExecutionCallableRunner(
           ^^^^^^^^^^^^^^^^^^^^^^^^
  File "/home/airflow/.local/lib/python3.12/site-packages/airflow/utils/operator_helpers.py", line 252, in run
    return self.func(*args, **kwargs)
           ^^^^^^^^^^^^^^^^^^^^^^^^^^
  File "/home/airflow/.local/lib/python3.12/site-packages/airflow/models/baseoperator.py", line 417, in wrapper
    return func(self, *args, **kwargs)
           ^^^^^^^^^^^^^^^^^^^^^^^^^^^
  File "/home/airflow/.local/lib/python3.12/site-packages/airflow/operators/python.py", line 238, in execute
    return_value = self.execute_callable()
                   ^^^^^^^^^^^^^^^^^^^^^^^
  File "/home/airflow/.local/lib/python3.12/site-packages/airflow/operators/python.py", line 256, in execute_callable
    return runner.run(*self.op_args, **self.op_kwargs)
           ^^^^^^^^^^^^^^^^^^^^^^^^^^^^^^^^^^^^^^^^^^^
  File "/home/airflow/.local/lib/python3.12/site-packages/airflow/utils/operator_helpers.py", line 252, in run
    return self.func(*args, **kwargs)
           ^^^^^^^^^^^^^^^^^^^^^^^^^^
  File "/opt/airflow/dags/refined/insert_data_to_3.py", line 43, in transform_data
    cursor.execute("""
psycopg2.errors.ForeignKeyViolation: insert or update on table "command" violates foreign key constraint "command_product_id_fkey"
DETAIL:  Key (product_id)=(2058) is not present in table "product".

[2024-11-18T22:41:05.281+0000] {local_task_job_runner.py:266} INFO - Task exited with return code 1
[2024-11-18T22:41:05.340+0000] {taskinstance.py:3895} INFO - 0 downstream tasks scheduled from follow-on schedule check
[2024-11-18T22:41:05.345+0000] {local_task_job_runner.py:245} INFO - ::endgroup::
