[2024-11-18T22:39:10.844+0000] {local_task_job_runner.py:123} INFO - ::group::Pre task execution logs
[2024-11-18T22:39:10.890+0000] {taskinstance.py:2613} INFO - Dependencies all met for dep_context=non-requeueable deps ti=<TaskInstance: load_customers_data_to_db.transform_data manual__2024-11-18T22:37:34.324485+00:00 [queued]>
[2024-11-18T22:39:10.904+0000] {taskinstance.py:2613} INFO - Dependencies all met for dep_context=requeueable deps ti=<TaskInstance: load_customers_data_to_db.transform_data manual__2024-11-18T22:37:34.324485+00:00 [queued]>
[2024-11-18T22:39:10.905+0000] {taskinstance.py:2866} INFO - Starting attempt 2 of 2
[2024-11-18T22:39:10.929+0000] {taskinstance.py:2889} INFO - Executing <Task(PythonOperator): transform_data> on 2024-11-18 22:37:34.324485+00:00
[2024-11-18T22:39:10.939+0000] {warnings.py:112} WARNING - /home/***/.local/lib/python3.12/site-packages/***/task/task_runner/standard_task_runner.py:70: DeprecationWarning: This process (pid=119) is multi-threaded, use of fork() may lead to deadlocks in the child.
  pid = os.fork()

[2024-11-18T22:39:10.942+0000] {standard_task_runner.py:72} INFO - Started process 121 to run task
[2024-11-18T22:39:10.943+0000] {standard_task_runner.py:104} INFO - Running: ['***', 'tasks', 'run', 'load_customers_data_to_db', 'transform_data', 'manual__2024-11-18T22:37:34.324485+00:00', '--job-id', '513', '--raw', '--subdir', 'DAGS_FOLDER/refined/insert_data_to_3.py', '--cfg-path', '/tmp/tmpw0r25bno']
[2024-11-18T22:39:10.945+0000] {standard_task_runner.py:105} INFO - Job 513: Subtask transform_data
[2024-11-18T22:39:11.024+0000] {task_command.py:467} INFO - Running <TaskInstance: load_customers_data_to_db.transform_data manual__2024-11-18T22:37:34.324485+00:00 [running]> on host c06adc74012b
[2024-11-18T22:39:11.218+0000] {taskinstance.py:3132} INFO - Exporting env vars: AIRFLOW_CTX_DAG_OWNER='***' AIRFLOW_CTX_DAG_ID='load_customers_data_to_db' AIRFLOW_CTX_TASK_ID='transform_data' AIRFLOW_CTX_EXECUTION_DATE='2024-11-18T22:37:34.324485+00:00' AIRFLOW_CTX_TRY_NUMBER='2' AIRFLOW_CTX_DAG_RUN_ID='manual__2024-11-18T22:37:34.324485+00:00'
[2024-11-18T22:39:11.220+0000] {logging_mixin.py:190} INFO - Task instance is in running state
[2024-11-18T22:39:11.221+0000] {logging_mixin.py:190} INFO -  Previous state of the Task instance: queued
[2024-11-18T22:39:11.222+0000] {logging_mixin.py:190} INFO - Current task name:transform_data state:running start_date:2024-11-18 22:39:10.891255+00:00
[2024-11-18T22:39:11.222+0000] {logging_mixin.py:190} INFO - Dag name:load_customers_data_to_db and current dag run status:running
[2024-11-18T22:39:11.223+0000] {taskinstance.py:731} INFO - ::endgroup::
[2024-11-18T22:39:11.237+0000] {base.py:84} INFO - Retrieving connection 'postgres_default'
[2024-11-18T22:39:11.259+0000] {insert_data_to_3.py:28} INFO - Nombre de lignes récupérées : 60
[2024-11-18T22:39:11.259+0000] {insert_data_to_3.py:32} INFO - Traitement de la ligne : (722, 'Keven Luciano', 20, 'kluciano0@dagondesign.com', 'Nigeria', 'NaN', 1298, 83, datetime.date(2021, 4, 16), 2058, 'Basil - Pesto Sauce', 412, Decimal('706.03'))
[2024-11-18T22:39:11.265+0000] {insert_data_to_3.py:63} ERROR - Erreur lors de l'insertion des données : relation "refined.purchase" does not exist
LINE 2:                 INSERT INTO refined.purchase (
                                    ^

[2024-11-18T22:39:11.269+0000] {taskinstance.py:3311} ERROR - Task failed with exception
Traceback (most recent call last):
  File "/home/airflow/.local/lib/python3.12/site-packages/airflow/models/taskinstance.py", line 767, in _execute_task
    result = _execute_callable(context=context, **execute_callable_kwargs)
             ^^^^^^^^^^^^^^^^^^^^^^^^^^^^^^^^^^^^^^^^^^^^^^^^^^^^^^^^^^^^^
  File "/home/airflow/.local/lib/python3.12/site-packages/airflow/models/taskinstance.py", line 733, in _execute_callable
    return ExecutionCallableRunner(
           ^^^^^^^^^^^^^^^^^^^^^^^^
  File "/home/airflow/.local/lib/python3.12/site-packages/airflow/utils/operator_helpers.py", line 252, in run
    return self.func(*args, **kwargs)
           ^^^^^^^^^^^^^^^^^^^^^^^^^^
  File "/home/airflow/.local/lib/python3.12/site-packages/airflow/models/baseoperator.py", line 417, in wrapper
    return func(self, *args, **kwargs)
           ^^^^^^^^^^^^^^^^^^^^^^^^^^^
  File "/home/airflow/.local/lib/python3.12/site-packages/airflow/operators/python.py", line 238, in execute
    return_value = self.execute_callable()
                   ^^^^^^^^^^^^^^^^^^^^^^^
  File "/home/airflow/.local/lib/python3.12/site-packages/airflow/operators/python.py", line 256, in execute_callable
    return runner.run(*self.op_args, **self.op_kwargs)
           ^^^^^^^^^^^^^^^^^^^^^^^^^^^^^^^^^^^^^^^^^^^
  File "/home/airflow/.local/lib/python3.12/site-packages/airflow/utils/operator_helpers.py", line 252, in run
    return self.func(*args, **kwargs)
           ^^^^^^^^^^^^^^^^^^^^^^^^^^
  File "/opt/airflow/dags/refined/insert_data_to_3.py", line 43, in transform_data
    cursor.execute("""
psycopg2.errors.UndefinedTable: relation "refined.purchase" does not exist
LINE 2:                 INSERT INTO refined.purchase (
                                    ^

[2024-11-18T22:39:11.290+0000] {logging_mixin.py:190} INFO - Task instance in failure state
[2024-11-18T22:39:11.291+0000] {logging_mixin.py:190} INFO - Task start:2024-11-18 22:39:10.891255+00:00 end:2024-11-18 22:39:11.289837+00:00 duration:0.398582
[2024-11-18T22:39:11.291+0000] {logging_mixin.py:190} INFO - Task:<Task(PythonOperator): transform_data> dag:<DAG: load_customers_data_to_db> dagrun:<DagRun load_customers_data_to_db @ 2024-11-18 22:37:34.324485+00:00: manual__2024-11-18T22:37:34.324485+00:00, state:running, queued_at: 2024-11-18 22:37:34.336220+00:00. externally triggered: True>
[2024-11-18T22:39:11.292+0000] {logging_mixin.py:190} INFO - Failure caused by relation "refined.purchase" does not exist
LINE 2:                 INSERT INTO refined.purchase (
                                    ^
[2024-11-18T22:39:11.293+0000] {taskinstance.py:1225} INFO - Marking task as FAILED. dag_id=load_customers_data_to_db, task_id=transform_data, run_id=manual__2024-11-18T22:37:34.324485+00:00, execution_date=20241118T223734, start_date=20241118T223910, end_date=20241118T223911
[2024-11-18T22:39:11.312+0000] {taskinstance.py:340} INFO - ::group::Post task execution logs
[2024-11-18T22:39:11.313+0000] {standard_task_runner.py:124} ERROR - Failed to execute job 513 for task transform_data (relation "refined.purchase" does not exist
LINE 2:                 INSERT INTO refined.purchase (
                                    ^
; 121)
Traceback (most recent call last):
  File "/home/airflow/.local/lib/python3.12/site-packages/airflow/task/task_runner/standard_task_runner.py", line 117, in _start_by_fork
    ret = args.func(args, dag=self.dag)
          ^^^^^^^^^^^^^^^^^^^^^^^^^^^^^
  File "/home/airflow/.local/lib/python3.12/site-packages/airflow/cli/cli_config.py", line 49, in command
    return func(*args, **kwargs)
           ^^^^^^^^^^^^^^^^^^^^^
  File "/home/airflow/.local/lib/python3.12/site-packages/airflow/utils/cli.py", line 116, in wrapper
    return f(*args, **kwargs)
           ^^^^^^^^^^^^^^^^^^
  File "/home/airflow/.local/lib/python3.12/site-packages/airflow/cli/commands/task_command.py", line 483, in task_run
    task_return_code = _run_task_by_selected_method(args, _dag, ti)
                       ^^^^^^^^^^^^^^^^^^^^^^^^^^^^^^^^^^^^^^^^^^^^
  File "/home/airflow/.local/lib/python3.12/site-packages/airflow/cli/commands/task_command.py", line 256, in _run_task_by_selected_method
    return _run_raw_task(args, ti)
           ^^^^^^^^^^^^^^^^^^^^^^^
  File "/home/airflow/.local/lib/python3.12/site-packages/airflow/cli/commands/task_command.py", line 341, in _run_raw_task
    return ti._run_raw_task(
           ^^^^^^^^^^^^^^^^^
  File "/home/airflow/.local/lib/python3.12/site-packages/airflow/utils/session.py", line 97, in wrapper
    return func(*args, session=session, **kwargs)
           ^^^^^^^^^^^^^^^^^^^^^^^^^^^^^^^^^^^^^^
  File "/home/airflow/.local/lib/python3.12/site-packages/airflow/models/taskinstance.py", line 3005, in _run_raw_task
    return _run_raw_task(
           ^^^^^^^^^^^^^^
  File "/home/airflow/.local/lib/python3.12/site-packages/airflow/models/taskinstance.py", line 273, in _run_raw_task
    TaskInstance._execute_task_with_callbacks(
  File "/home/airflow/.local/lib/python3.12/site-packages/airflow/models/taskinstance.py", line 3159, in _execute_task_with_callbacks
    result = self._execute_task(context, task_orig)
             ^^^^^^^^^^^^^^^^^^^^^^^^^^^^^^^^^^^^^^
  File "/home/airflow/.local/lib/python3.12/site-packages/airflow/models/taskinstance.py", line 3183, in _execute_task
    return _execute_task(self, context, task_orig)
           ^^^^^^^^^^^^^^^^^^^^^^^^^^^^^^^^^^^^^^^
  File "/home/airflow/.local/lib/python3.12/site-packages/airflow/models/taskinstance.py", line 767, in _execute_task
    result = _execute_callable(context=context, **execute_callable_kwargs)
             ^^^^^^^^^^^^^^^^^^^^^^^^^^^^^^^^^^^^^^^^^^^^^^^^^^^^^^^^^^^^^
  File "/home/airflow/.local/lib/python3.12/site-packages/airflow/models/taskinstance.py", line 733, in _execute_callable
    return ExecutionCallableRunner(
           ^^^^^^^^^^^^^^^^^^^^^^^^
  File "/home/airflow/.local/lib/python3.12/site-packages/airflow/utils/operator_helpers.py", line 252, in run
    return self.func(*args, **kwargs)
           ^^^^^^^^^^^^^^^^^^^^^^^^^^
  File "/home/airflow/.local/lib/python3.12/site-packages/airflow/models/baseoperator.py", line 417, in wrapper
    return func(self, *args, **kwargs)
           ^^^^^^^^^^^^^^^^^^^^^^^^^^^
  File "/home/airflow/.local/lib/python3.12/site-packages/airflow/operators/python.py", line 238, in execute
    return_value = self.execute_callable()
                   ^^^^^^^^^^^^^^^^^^^^^^^
  File "/home/airflow/.local/lib/python3.12/site-packages/airflow/operators/python.py", line 256, in execute_callable
    return runner.run(*self.op_args, **self.op_kwargs)
           ^^^^^^^^^^^^^^^^^^^^^^^^^^^^^^^^^^^^^^^^^^^
  File "/home/airflow/.local/lib/python3.12/site-packages/airflow/utils/operator_helpers.py", line 252, in run
    return self.func(*args, **kwargs)
           ^^^^^^^^^^^^^^^^^^^^^^^^^^
  File "/opt/airflow/dags/refined/insert_data_to_3.py", line 43, in transform_data
    cursor.execute("""
psycopg2.errors.UndefinedTable: relation "refined.purchase" does not exist
LINE 2:                 INSERT INTO refined.purchase (
                                    ^

[2024-11-18T22:39:11.360+0000] {local_task_job_runner.py:266} INFO - Task exited with return code 1
[2024-11-18T22:39:11.442+0000] {taskinstance.py:3895} INFO - 0 downstream tasks scheduled from follow-on schedule check
[2024-11-18T22:39:11.450+0000] {local_task_job_runner.py:245} INFO - ::endgroup::
