[2024-11-18T21:30:27.925+0000] {local_task_job_runner.py:123} INFO - ::group::Pre task execution logs
[2024-11-18T21:30:27.966+0000] {taskinstance.py:2613} INFO - Dependencies all met for dep_context=non-requeueable deps ti=<TaskInstance: raw_api_sales_data.insert_sales_data scheduled__2024-11-18T21:20:00+00:00 [queued]>
[2024-11-18T21:30:27.988+0000] {taskinstance.py:2613} INFO - Dependencies all met for dep_context=requeueable deps ti=<TaskInstance: raw_api_sales_data.insert_sales_data scheduled__2024-11-18T21:20:00+00:00 [queued]>
[2024-11-18T21:30:27.990+0000] {taskinstance.py:2866} INFO - Starting attempt 2 of 2
[2024-11-18T21:30:28.027+0000] {taskinstance.py:2889} INFO - Executing <Task(PythonOperator): insert_sales_data> on 2024-11-18 21:20:00+00:00
[2024-11-18T21:30:28.039+0000] {warnings.py:112} WARNING - /home/***/.local/lib/python3.12/site-packages/***/task/task_runner/standard_task_runner.py:70: DeprecationWarning: This process (pid=4534) is multi-threaded, use of fork() may lead to deadlocks in the child.
  pid = os.fork()

[2024-11-18T21:30:28.044+0000] {standard_task_runner.py:72} INFO - Started process 4536 to run task
[2024-11-18T21:30:28.044+0000] {standard_task_runner.py:104} INFO - Running: ['***', 'tasks', 'run', 'raw_api_sales_data', 'insert_sales_data', 'scheduled__2024-11-18T21:20:00+00:00', '--job-id', '463', '--raw', '--subdir', 'DAGS_FOLDER/raw/__pycache__/fetch_data.py', '--cfg-path', '/tmp/tmpactethb9']
[2024-11-18T21:30:28.048+0000] {standard_task_runner.py:105} INFO - Job 463: Subtask insert_sales_data
[2024-11-18T21:30:28.168+0000] {task_command.py:467} INFO - Running <TaskInstance: raw_api_sales_data.insert_sales_data scheduled__2024-11-18T21:20:00+00:00 [running]> on host c06adc74012b
[2024-11-18T21:30:28.814+0000] {taskinstance.py:3132} INFO - Exporting env vars: AIRFLOW_CTX_DAG_OWNER='***' AIRFLOW_CTX_DAG_ID='raw_api_sales_data' AIRFLOW_CTX_TASK_ID='insert_sales_data' AIRFLOW_CTX_EXECUTION_DATE='2024-11-18T21:20:00+00:00' AIRFLOW_CTX_TRY_NUMBER='2' AIRFLOW_CTX_DAG_RUN_ID='scheduled__2024-11-18T21:20:00+00:00'
[2024-11-18T21:30:28.816+0000] {logging_mixin.py:190} INFO - Task instance is in running state
[2024-11-18T21:30:28.817+0000] {logging_mixin.py:190} INFO -  Previous state of the Task instance: queued
[2024-11-18T21:30:28.818+0000] {logging_mixin.py:190} INFO - Current task name:insert_sales_data state:running start_date:2024-11-18 21:30:27.967325+00:00
[2024-11-18T21:30:28.819+0000] {logging_mixin.py:190} INFO - Dag name:raw_api_sales_data and current dag run status:running
[2024-11-18T21:30:28.820+0000] {taskinstance.py:731} INFO - ::endgroup::
[2024-11-18T21:30:28.870+0000] {base.py:84} INFO - Retrieving connection 'postgres_default'
[2024-11-18T21:30:28.896+0000] {fetch_data.py:75} ERROR - Failed to insert data into PostgreSQL: relation "raw.sales" does not exist
LINE 2:         INSERT INTO raw.sales (
                            ^

[2024-11-18T21:30:28.901+0000] {taskinstance.py:3311} ERROR - Task failed with exception
Traceback (most recent call last):
  File "/home/airflow/.local/lib/python3.12/site-packages/airflow/models/taskinstance.py", line 767, in _execute_task
    result = _execute_callable(context=context, **execute_callable_kwargs)
             ^^^^^^^^^^^^^^^^^^^^^^^^^^^^^^^^^^^^^^^^^^^^^^^^^^^^^^^^^^^^^
  File "/home/airflow/.local/lib/python3.12/site-packages/airflow/models/taskinstance.py", line 733, in _execute_callable
    return ExecutionCallableRunner(
           ^^^^^^^^^^^^^^^^^^^^^^^^
  File "/home/airflow/.local/lib/python3.12/site-packages/airflow/utils/operator_helpers.py", line 252, in run
    return self.func(*args, **kwargs)
           ^^^^^^^^^^^^^^^^^^^^^^^^^^
  File "/home/airflow/.local/lib/python3.12/site-packages/airflow/models/baseoperator.py", line 417, in wrapper
    return func(self, *args, **kwargs)
           ^^^^^^^^^^^^^^^^^^^^^^^^^^^
  File "/home/airflow/.local/lib/python3.12/site-packages/airflow/operators/python.py", line 238, in execute
    return_value = self.execute_callable()
                   ^^^^^^^^^^^^^^^^^^^^^^^
  File "/home/airflow/.local/lib/python3.12/site-packages/airflow/operators/python.py", line 256, in execute_callable
    return runner.run(*self.op_args, **self.op_kwargs)
           ^^^^^^^^^^^^^^^^^^^^^^^^^^^^^^^^^^^^^^^^^^^
  File "/home/airflow/.local/lib/python3.12/site-packages/airflow/utils/operator_helpers.py", line 252, in run
    return self.func(*args, **kwargs)
           ^^^^^^^^^^^^^^^^^^^^^^^^^^
  File "/opt/airflow/dags/raw/__pycache__/fetch_data.py", line 66, in insert_sales_data
    cursor.execute(insert_query, (
psycopg2.errors.UndefinedTable: relation "raw.sales" does not exist
LINE 2:         INSERT INTO raw.sales (
                            ^

[2024-11-18T21:30:28.935+0000] {logging_mixin.py:190} INFO - Task instance in failure state
[2024-11-18T21:30:28.937+0000] {logging_mixin.py:190} INFO - Task start:2024-11-18 21:30:27.967325+00:00 end:2024-11-18 21:30:28.934747+00:00 duration:0.967422
[2024-11-18T21:30:28.938+0000] {logging_mixin.py:190} INFO - Task:<Task(PythonOperator): insert_sales_data> dag:<DAG: raw_api_sales_data> dagrun:<DagRun raw_api_sales_data @ 2024-11-18 21:20:00+00:00: scheduled__2024-11-18T21:20:00+00:00, state:running, queued_at: 2024-11-18 21:30:00.198979+00:00. externally triggered: False>
[2024-11-18T21:30:28.938+0000] {logging_mixin.py:190} INFO - Failure caused by relation "raw.sales" does not exist
LINE 2:         INSERT INTO raw.sales (
                            ^
[2024-11-18T21:30:28.939+0000] {taskinstance.py:1225} INFO - Marking task as FAILED. dag_id=raw_api_sales_data, task_id=insert_sales_data, run_id=scheduled__2024-11-18T21:20:00+00:00, execution_date=20241118T212000, start_date=20241118T213027, end_date=20241118T213028
[2024-11-18T21:30:28.970+0000] {taskinstance.py:340} INFO - ::group::Post task execution logs
[2024-11-18T21:30:28.971+0000] {standard_task_runner.py:124} ERROR - Failed to execute job 463 for task insert_sales_data (relation "raw.sales" does not exist
LINE 2:         INSERT INTO raw.sales (
                            ^
; 4536)
Traceback (most recent call last):
  File "/home/airflow/.local/lib/python3.12/site-packages/airflow/task/task_runner/standard_task_runner.py", line 117, in _start_by_fork
    ret = args.func(args, dag=self.dag)
          ^^^^^^^^^^^^^^^^^^^^^^^^^^^^^
  File "/home/airflow/.local/lib/python3.12/site-packages/airflow/cli/cli_config.py", line 49, in command
    return func(*args, **kwargs)
           ^^^^^^^^^^^^^^^^^^^^^
  File "/home/airflow/.local/lib/python3.12/site-packages/airflow/utils/cli.py", line 116, in wrapper
    return f(*args, **kwargs)
           ^^^^^^^^^^^^^^^^^^
  File "/home/airflow/.local/lib/python3.12/site-packages/airflow/cli/commands/task_command.py", line 483, in task_run
    task_return_code = _run_task_by_selected_method(args, _dag, ti)
                       ^^^^^^^^^^^^^^^^^^^^^^^^^^^^^^^^^^^^^^^^^^^^
  File "/home/airflow/.local/lib/python3.12/site-packages/airflow/cli/commands/task_command.py", line 256, in _run_task_by_selected_method
    return _run_raw_task(args, ti)
           ^^^^^^^^^^^^^^^^^^^^^^^
  File "/home/airflow/.local/lib/python3.12/site-packages/airflow/cli/commands/task_command.py", line 341, in _run_raw_task
    return ti._run_raw_task(
           ^^^^^^^^^^^^^^^^^
  File "/home/airflow/.local/lib/python3.12/site-packages/airflow/utils/session.py", line 97, in wrapper
    return func(*args, session=session, **kwargs)
           ^^^^^^^^^^^^^^^^^^^^^^^^^^^^^^^^^^^^^^
  File "/home/airflow/.local/lib/python3.12/site-packages/airflow/models/taskinstance.py", line 3005, in _run_raw_task
    return _run_raw_task(
           ^^^^^^^^^^^^^^
  File "/home/airflow/.local/lib/python3.12/site-packages/airflow/models/taskinstance.py", line 273, in _run_raw_task
    TaskInstance._execute_task_with_callbacks(
  File "/home/airflow/.local/lib/python3.12/site-packages/airflow/models/taskinstance.py", line 3159, in _execute_task_with_callbacks
    result = self._execute_task(context, task_orig)
             ^^^^^^^^^^^^^^^^^^^^^^^^^^^^^^^^^^^^^^
  File "/home/airflow/.local/lib/python3.12/site-packages/airflow/models/taskinstance.py", line 3183, in _execute_task
    return _execute_task(self, context, task_orig)
           ^^^^^^^^^^^^^^^^^^^^^^^^^^^^^^^^^^^^^^^
  File "/home/airflow/.local/lib/python3.12/site-packages/airflow/models/taskinstance.py", line 767, in _execute_task
    result = _execute_callable(context=context, **execute_callable_kwargs)
             ^^^^^^^^^^^^^^^^^^^^^^^^^^^^^^^^^^^^^^^^^^^^^^^^^^^^^^^^^^^^^
  File "/home/airflow/.local/lib/python3.12/site-packages/airflow/models/taskinstance.py", line 733, in _execute_callable
    return ExecutionCallableRunner(
           ^^^^^^^^^^^^^^^^^^^^^^^^
  File "/home/airflow/.local/lib/python3.12/site-packages/airflow/utils/operator_helpers.py", line 252, in run
    return self.func(*args, **kwargs)
           ^^^^^^^^^^^^^^^^^^^^^^^^^^
  File "/home/airflow/.local/lib/python3.12/site-packages/airflow/models/baseoperator.py", line 417, in wrapper
    return func(self, *args, **kwargs)
           ^^^^^^^^^^^^^^^^^^^^^^^^^^^
  File "/home/airflow/.local/lib/python3.12/site-packages/airflow/operators/python.py", line 238, in execute
    return_value = self.execute_callable()
                   ^^^^^^^^^^^^^^^^^^^^^^^
  File "/home/airflow/.local/lib/python3.12/site-packages/airflow/operators/python.py", line 256, in execute_callable
    return runner.run(*self.op_args, **self.op_kwargs)
           ^^^^^^^^^^^^^^^^^^^^^^^^^^^^^^^^^^^^^^^^^^^
  File "/home/airflow/.local/lib/python3.12/site-packages/airflow/utils/operator_helpers.py", line 252, in run
    return self.func(*args, **kwargs)
           ^^^^^^^^^^^^^^^^^^^^^^^^^^
  File "/opt/airflow/dags/raw/__pycache__/fetch_data.py", line 66, in insert_sales_data
    cursor.execute(insert_query, (
psycopg2.errors.UndefinedTable: relation "raw.sales" does not exist
LINE 2:         INSERT INTO raw.sales (
                            ^

[2024-11-18T21:30:29.026+0000] {local_task_job_runner.py:266} INFO - Task exited with return code 1
[2024-11-18T21:30:29.060+0000] {taskinstance.py:3895} INFO - 0 downstream tasks scheduled from follow-on schedule check
[2024-11-18T21:30:29.063+0000] {local_task_job_runner.py:245} INFO - ::endgroup::
