[2024-11-17T23:01:41.624+0000] {local_task_job_runner.py:123} INFO - ::group::Pre task execution logs
[2024-11-17T23:01:41.661+0000] {taskinstance.py:2613} INFO - Dependencies all met for dep_context=non-requeueable deps ti=<TaskInstance: raw_api_sales_data.insert_sales_data manual__2024-11-17T23:01:13.553211+00:00 [queued]>
[2024-11-17T23:01:41.678+0000] {taskinstance.py:2613} INFO - Dependencies all met for dep_context=requeueable deps ti=<TaskInstance: raw_api_sales_data.insert_sales_data manual__2024-11-17T23:01:13.553211+00:00 [queued]>
[2024-11-17T23:01:41.679+0000] {taskinstance.py:2866} INFO - Starting attempt 2 of 2
[2024-11-17T23:01:41.727+0000] {taskinstance.py:2889} INFO - Executing <Task(PythonOperator): insert_sales_data> on 2024-11-17 23:01:13.553211+00:00
[2024-11-17T23:01:41.739+0000] {warnings.py:112} WARNING - /home/***/.local/lib/python3.12/site-packages/***/task/task_runner/standard_task_runner.py:70: DeprecationWarning: This process (pid=656) is multi-threaded, use of fork() may lead to deadlocks in the child.
  pid = os.fork()

[2024-11-17T23:01:41.742+0000] {standard_task_runner.py:72} INFO - Started process 658 to run task
[2024-11-17T23:01:41.744+0000] {standard_task_runner.py:104} INFO - Running: ['***', 'tasks', 'run', 'raw_api_sales_data', 'insert_sales_data', 'manual__2024-11-17T23:01:13.553211+00:00', '--job-id', '148', '--raw', '--subdir', 'DAGS_FOLDER/fetch_data.py', '--cfg-path', '/tmp/tmpt65eijwp']
[2024-11-17T23:01:41.747+0000] {standard_task_runner.py:105} INFO - Job 148: Subtask insert_sales_data
[2024-11-17T23:01:41.946+0000] {task_command.py:467} INFO - Running <TaskInstance: raw_api_sales_data.insert_sales_data manual__2024-11-17T23:01:13.553211+00:00 [running]> on host 525767e32e17
[2024-11-17T23:01:42.858+0000] {taskinstance.py:3132} INFO - Exporting env vars: AIRFLOW_CTX_DAG_OWNER='***' AIRFLOW_CTX_DAG_ID='raw_api_sales_data' AIRFLOW_CTX_TASK_ID='insert_sales_data' AIRFLOW_CTX_EXECUTION_DATE='2024-11-17T23:01:13.553211+00:00' AIRFLOW_CTX_TRY_NUMBER='2' AIRFLOW_CTX_DAG_RUN_ID='manual__2024-11-17T23:01:13.553211+00:00'
[2024-11-17T23:01:42.860+0000] {logging_mixin.py:190} INFO - Task instance is in running state
[2024-11-17T23:01:42.861+0000] {logging_mixin.py:190} INFO -  Previous state of the Task instance: queued
[2024-11-17T23:01:42.862+0000] {logging_mixin.py:190} INFO - Current task name:insert_sales_data state:running start_date:2024-11-17 23:01:41.662173+00:00
[2024-11-17T23:01:42.863+0000] {logging_mixin.py:190} INFO - Dag name:raw_api_sales_data and current dag run status:running
[2024-11-17T23:01:42.864+0000] {taskinstance.py:731} INFO - ::endgroup::
[2024-11-17T23:01:42.886+0000] {logging_mixin.py:190} INFO - sales_data: [{'customer_id': 946, 'customer_name': 'Alec Espada', 'age': 20, 'email': 'aespada0@sourceforge.net', 'country': 'China', 'postal_code': nan, 'purchase_id': 453, 'purchase_quantity': 52, 'purchase_date': '5/17/2021', 'product_id': 2023, 'product_name': 'Butter Sweet', 'quantity': 737, 'total_price': 1553.42, 'price_unit': 414.78}, {'customer_id': 996, 'customer_name': 'Crosby Gude', 'age': 64, 'email': 'cgude1@amazon.de', 'country': 'France', 'postal_code': '75188 CEDEX 04', 'purchase_id': 1228, 'purchase_quantity': 67, 'purchase_date': '5/11/2021', 'product_id': 2029, 'product_name': 'Ecolab - Mikroklene 4/4 L', 'quantity': 159, 'total_price': 3193.07, 'price_unit': 914.23}, {'customer_id': 976, 'customer_name': 'Sigismond Scyner', 'age': 33, 'email': 'sscyner2@t-online.de', 'country': 'China', 'postal_code': nan, 'purchase_id': 1581, 'purchase_quantity': 68, 'purchase_date': '8/20/2021', 'product_id': 2039, 'product_name': 'Scotch - Queen Anne', 'quantity': 922, 'total_price': 8520.23, 'price_unit': 332.11}, {'customer_id': 927, 'customer_name': 'Hannie Cadany', 'age': 45, 'email': 'hcadany3@vimeo.com', 'country': 'Sweden', 'postal_code': '504 67', 'purchase_id': 1066, 'purchase_quantity': 96, 'purchase_date': '2/7/2021', 'product_id': 2030, 'product_name': 'Juice - Lime', 'quantity': 974, 'total_price': 7638.4, 'price_unit': 941.92}, {'customer_id': 726, 'customer_name': 'Heddie Brecon', 'age': 31, 'email': 'hbrecon4@statcounter.com', 'country': 'Finland', 'postal_code': '14300', 'purchase_id': 843, 'purchase_quantity': 35, 'purchase_date': '4/5/2021', 'product_id': 2071, 'product_name': 'Mushroom - Enoki, Fresh', 'quantity': 149, 'total_price': 9628.67, 'price_unit': 372.32}, {'customer_id': 10, 'customer_name': 'Fina Willimont', 'age': 23, 'email': 'fwillimont5@wix.com', 'country': 'Poland', 'postal_code': '37-560', 'purchase_id': 194, 'purchase_quantity': 7, 'purchase_date': '8/5/2021', 'product_id': 2034, 'product_name': 'Wanton Wrap', 'quantity': 773, 'total_price': 7680.57, 'price_unit': 25.07}, {'customer_id': 110, 'customer_name': 'Juditha Sapseed', 'age': 71, 'email': 'jsapseed6@rediff.com', 'country': 'China', 'postal_code': nan, 'purchase_id': 1402, 'purchase_quantity': 3, 'purchase_date': '4/8/2021', 'product_id': 2045, 'product_name': 'Stock - Veal, White', 'quantity': 923, 'total_price': 9729.99, 'price_unit': 695.71}, {'customer_id': 487, 'customer_name': 'Nonie Ferenczi', 'age': 32, 'email': 'nferenczi7@hibu.com', 'country': 'Palestinian Territory', 'postal_code': nan, 'purchase_id': 249, 'purchase_quantity': 46, 'purchase_date': '5/1/2021', 'product_id': 2013, 'product_name': 'Wine - Mondavi Coastal Private', 'quantity': 582, 'total_price': 6578.13, 'price_unit': 60.27}, {'customer_id': 391, 'customer_name': 'Whit Van Hove', 'age': 75, 'email': 'wvan8@vimeo.com', 'country': 'Portugal', 'postal_code': '4615-131', 'purchase_id': 362, 'purchase_quantity': 37, 'purchase_date': '10/16/2021', 'product_id': 2083, 'product_name': 'Milk Powder', 'quantity': 453, 'total_price': 533.2, 'price_unit': 230.79}, {'customer_id': 380, 'customer_name': 'Charla Caseri', 'age': 51, 'email': 'ccaseri9@wordpress.org', 'country': 'Mexico', 'postal_code': '85227', 'purchase_id': 1542, 'purchase_quantity': 44, 'purchase_date': '5/22/2021', 'product_id': 2057, 'product_name': 'Rolled Oats', 'quantity': 494, 'total_price': 4303.96, 'price_unit': 801.64}]
[2024-11-17T23:01:42.907+0000] {base.py:84} INFO - Retrieving connection 'postgres_default'
[2024-11-17T23:01:42.910+0000] {taskinstance.py:3311} ERROR - Task failed with exception
Traceback (most recent call last):
  File "/home/airflow/.local/lib/python3.12/site-packages/airflow/models/taskinstance.py", line 767, in _execute_task
    result = _execute_callable(context=context, **execute_callable_kwargs)
             ^^^^^^^^^^^^^^^^^^^^^^^^^^^^^^^^^^^^^^^^^^^^^^^^^^^^^^^^^^^^^
  File "/home/airflow/.local/lib/python3.12/site-packages/airflow/models/taskinstance.py", line 733, in _execute_callable
    return ExecutionCallableRunner(
           ^^^^^^^^^^^^^^^^^^^^^^^^
  File "/home/airflow/.local/lib/python3.12/site-packages/airflow/utils/operator_helpers.py", line 252, in run
    return self.func(*args, **kwargs)
           ^^^^^^^^^^^^^^^^^^^^^^^^^^
  File "/home/airflow/.local/lib/python3.12/site-packages/airflow/models/baseoperator.py", line 417, in wrapper
    return func(self, *args, **kwargs)
           ^^^^^^^^^^^^^^^^^^^^^^^^^^^
  File "/home/airflow/.local/lib/python3.12/site-packages/airflow/operators/python.py", line 238, in execute
    return_value = self.execute_callable()
                   ^^^^^^^^^^^^^^^^^^^^^^^
  File "/home/airflow/.local/lib/python3.12/site-packages/airflow/operators/python.py", line 256, in execute_callable
    return runner.run(*self.op_args, **self.op_kwargs)
           ^^^^^^^^^^^^^^^^^^^^^^^^^^^^^^^^^^^^^^^^^^^
  File "/home/airflow/.local/lib/python3.12/site-packages/airflow/utils/operator_helpers.py", line 252, in run
    return self.func(*args, **kwargs)
           ^^^^^^^^^^^^^^^^^^^^^^^^^^
  File "/opt/airflow/dags/fetch_data.py", line 61, in insert_sales_data
    conn = hook.get_conn()
           ^^^^^^^^^^^^^^^
  File "/home/airflow/.local/lib/python3.12/site-packages/airflow/providers/postgres/hooks/postgres.py", line 181, in get_conn
    self.conn = psycopg2.connect(**conn_args)
                ^^^^^^^^^^^^^^^^^^^^^^^^^^^^^
  File "/home/airflow/.local/lib/python3.12/site-packages/psycopg2/__init__.py", line 122, in connect
    conn = _connect(dsn, connection_factory=connection_factory, **kwasync)
           ^^^^^^^^^^^^^^^^^^^^^^^^^^^^^^^^^^^^^^^^^^^^^^^^^^^^^^^^^^^^^^^
psycopg2.OperationalError: connection to server at "localhost" (::1), port 5432 failed: Connection refused
	Is the server running on that host and accepting TCP/IP connections?
connection to server at "localhost" (127.0.0.1), port 5432 failed: Connection refused
	Is the server running on that host and accepting TCP/IP connections?

[2024-11-17T23:01:42.936+0000] {logging_mixin.py:190} INFO - Task instance in failure state
[2024-11-17T23:01:42.937+0000] {logging_mixin.py:190} INFO - Task start:2024-11-17 23:01:41.662173+00:00 end:2024-11-17 23:01:42.935342+00:00 duration:1.273169
[2024-11-17T23:01:42.938+0000] {logging_mixin.py:190} INFO - Task:<Task(PythonOperator): insert_sales_data> dag:<DAG: raw_api_sales_data> dagrun:<DagRun raw_api_sales_data @ 2024-11-17 23:01:13.553211+00:00: manual__2024-11-17T23:01:13.553211+00:00, state:running, queued_at: 2024-11-17 23:01:13.572494+00:00. externally triggered: True>
[2024-11-17T23:01:42.939+0000] {logging_mixin.py:190} INFO - Failure caused by connection to server at "localhost" (::1), port 5432 failed: Connection refused
	Is the server running on that host and accepting TCP/IP connections?
connection to server at "localhost" (127.0.0.1), port 5432 failed: Connection refused
	Is the server running on that host and accepting TCP/IP connections?
[2024-11-17T23:01:42.940+0000] {taskinstance.py:1225} INFO - Marking task as FAILED. dag_id=raw_api_sales_data, task_id=insert_sales_data, run_id=manual__2024-11-17T23:01:13.553211+00:00, execution_date=20241117T230113, start_date=20241117T230141, end_date=20241117T230142
[2024-11-17T23:01:42.966+0000] {taskinstance.py:340} INFO - ::group::Post task execution logs
[2024-11-17T23:01:42.968+0000] {standard_task_runner.py:124} ERROR - Failed to execute job 148 for task insert_sales_data (connection to server at "localhost" (::1), port 5432 failed: Connection refused
	Is the server running on that host and accepting TCP/IP connections?
connection to server at "localhost" (127.0.0.1), port 5432 failed: Connection refused
	Is the server running on that host and accepting TCP/IP connections?
; 658)
Traceback (most recent call last):
  File "/home/airflow/.local/lib/python3.12/site-packages/airflow/task/task_runner/standard_task_runner.py", line 117, in _start_by_fork
    ret = args.func(args, dag=self.dag)
          ^^^^^^^^^^^^^^^^^^^^^^^^^^^^^
  File "/home/airflow/.local/lib/python3.12/site-packages/airflow/cli/cli_config.py", line 49, in command
    return func(*args, **kwargs)
           ^^^^^^^^^^^^^^^^^^^^^
  File "/home/airflow/.local/lib/python3.12/site-packages/airflow/utils/cli.py", line 116, in wrapper
    return f(*args, **kwargs)
           ^^^^^^^^^^^^^^^^^^
  File "/home/airflow/.local/lib/python3.12/site-packages/airflow/cli/commands/task_command.py", line 483, in task_run
    task_return_code = _run_task_by_selected_method(args, _dag, ti)
                       ^^^^^^^^^^^^^^^^^^^^^^^^^^^^^^^^^^^^^^^^^^^^
  File "/home/airflow/.local/lib/python3.12/site-packages/airflow/cli/commands/task_command.py", line 256, in _run_task_by_selected_method
    return _run_raw_task(args, ti)
           ^^^^^^^^^^^^^^^^^^^^^^^
  File "/home/airflow/.local/lib/python3.12/site-packages/airflow/cli/commands/task_command.py", line 341, in _run_raw_task
    return ti._run_raw_task(
           ^^^^^^^^^^^^^^^^^
  File "/home/airflow/.local/lib/python3.12/site-packages/airflow/utils/session.py", line 97, in wrapper
    return func(*args, session=session, **kwargs)
           ^^^^^^^^^^^^^^^^^^^^^^^^^^^^^^^^^^^^^^
  File "/home/airflow/.local/lib/python3.12/site-packages/airflow/models/taskinstance.py", line 3005, in _run_raw_task
    return _run_raw_task(
           ^^^^^^^^^^^^^^
  File "/home/airflow/.local/lib/python3.12/site-packages/airflow/models/taskinstance.py", line 273, in _run_raw_task
    TaskInstance._execute_task_with_callbacks(
  File "/home/airflow/.local/lib/python3.12/site-packages/airflow/models/taskinstance.py", line 3159, in _execute_task_with_callbacks
    result = self._execute_task(context, task_orig)
             ^^^^^^^^^^^^^^^^^^^^^^^^^^^^^^^^^^^^^^
  File "/home/airflow/.local/lib/python3.12/site-packages/airflow/models/taskinstance.py", line 3183, in _execute_task
    return _execute_task(self, context, task_orig)
           ^^^^^^^^^^^^^^^^^^^^^^^^^^^^^^^^^^^^^^^
  File "/home/airflow/.local/lib/python3.12/site-packages/airflow/models/taskinstance.py", line 767, in _execute_task
    result = _execute_callable(context=context, **execute_callable_kwargs)
             ^^^^^^^^^^^^^^^^^^^^^^^^^^^^^^^^^^^^^^^^^^^^^^^^^^^^^^^^^^^^^
  File "/home/airflow/.local/lib/python3.12/site-packages/airflow/models/taskinstance.py", line 733, in _execute_callable
    return ExecutionCallableRunner(
           ^^^^^^^^^^^^^^^^^^^^^^^^
  File "/home/airflow/.local/lib/python3.12/site-packages/airflow/utils/operator_helpers.py", line 252, in run
    return self.func(*args, **kwargs)
           ^^^^^^^^^^^^^^^^^^^^^^^^^^
  File "/home/airflow/.local/lib/python3.12/site-packages/airflow/models/baseoperator.py", line 417, in wrapper
    return func(self, *args, **kwargs)
           ^^^^^^^^^^^^^^^^^^^^^^^^^^^
  File "/home/airflow/.local/lib/python3.12/site-packages/airflow/operators/python.py", line 238, in execute
    return_value = self.execute_callable()
                   ^^^^^^^^^^^^^^^^^^^^^^^
  File "/home/airflow/.local/lib/python3.12/site-packages/airflow/operators/python.py", line 256, in execute_callable
    return runner.run(*self.op_args, **self.op_kwargs)
           ^^^^^^^^^^^^^^^^^^^^^^^^^^^^^^^^^^^^^^^^^^^
  File "/home/airflow/.local/lib/python3.12/site-packages/airflow/utils/operator_helpers.py", line 252, in run
    return self.func(*args, **kwargs)
           ^^^^^^^^^^^^^^^^^^^^^^^^^^
  File "/opt/airflow/dags/fetch_data.py", line 61, in insert_sales_data
    conn = hook.get_conn()
           ^^^^^^^^^^^^^^^
  File "/home/airflow/.local/lib/python3.12/site-packages/airflow/providers/postgres/hooks/postgres.py", line 181, in get_conn
    self.conn = psycopg2.connect(**conn_args)
                ^^^^^^^^^^^^^^^^^^^^^^^^^^^^^
  File "/home/airflow/.local/lib/python3.12/site-packages/psycopg2/__init__.py", line 122, in connect
    conn = _connect(dsn, connection_factory=connection_factory, **kwasync)
           ^^^^^^^^^^^^^^^^^^^^^^^^^^^^^^^^^^^^^^^^^^^^^^^^^^^^^^^^^^^^^^^
psycopg2.OperationalError: connection to server at "localhost" (::1), port 5432 failed: Connection refused
	Is the server running on that host and accepting TCP/IP connections?
connection to server at "localhost" (127.0.0.1), port 5432 failed: Connection refused
	Is the server running on that host and accepting TCP/IP connections?

[2024-11-17T23:01:43.047+0000] {local_task_job_runner.py:266} INFO - Task exited with return code 1
[2024-11-17T23:01:43.102+0000] {taskinstance.py:3895} INFO - 0 downstream tasks scheduled from follow-on schedule check
[2024-11-17T23:01:43.114+0000] {local_task_job_runner.py:245} INFO - ::endgroup::
