[2024-11-17T23:23:16.068+0000] {local_task_job_runner.py:123} INFO - ::group::Pre task execution logs
[2024-11-17T23:23:16.082+0000] {taskinstance.py:2613} INFO - Dependencies all met for dep_context=non-requeueable deps ti=<TaskInstance: raw_api_sales_data.insert_sales_data manual__2024-11-17T23:23:03.350557+00:00 [queued]>
[2024-11-17T23:23:16.090+0000] {taskinstance.py:2613} INFO - Dependencies all met for dep_context=requeueable deps ti=<TaskInstance: raw_api_sales_data.insert_sales_data manual__2024-11-17T23:23:03.350557+00:00 [queued]>
[2024-11-17T23:23:16.091+0000] {taskinstance.py:2866} INFO - Starting attempt 2 of 2
[2024-11-17T23:23:16.104+0000] {taskinstance.py:2889} INFO - Executing <Task(PythonOperator): insert_sales_data> on 2024-11-17 23:23:03.350557+00:00
[2024-11-17T23:23:16.109+0000] {warnings.py:112} WARNING - /home/***/.local/lib/python3.12/site-packages/***/task/task_runner/standard_task_runner.py:70: DeprecationWarning: This process (pid=974) is multi-threaded, use of fork() may lead to deadlocks in the child.
  pid = os.fork()

[2024-11-17T23:23:16.111+0000] {standard_task_runner.py:72} INFO - Started process 976 to run task
[2024-11-17T23:23:16.111+0000] {standard_task_runner.py:104} INFO - Running: ['***', 'tasks', 'run', 'raw_api_sales_data', 'insert_sales_data', 'manual__2024-11-17T23:23:03.350557+00:00', '--job-id', '166', '--raw', '--subdir', 'DAGS_FOLDER/fetch_data.py', '--cfg-path', '/tmp/tmp9yv7x71n']
[2024-11-17T23:23:16.113+0000] {standard_task_runner.py:105} INFO - Job 166: Subtask insert_sales_data
[2024-11-17T23:23:16.155+0000] {task_command.py:467} INFO - Running <TaskInstance: raw_api_sales_data.insert_sales_data manual__2024-11-17T23:23:03.350557+00:00 [running]> on host 525767e32e17
[2024-11-17T23:23:16.403+0000] {taskinstance.py:3132} INFO - Exporting env vars: AIRFLOW_CTX_DAG_OWNER='***' AIRFLOW_CTX_DAG_ID='raw_api_sales_data' AIRFLOW_CTX_TASK_ID='insert_sales_data' AIRFLOW_CTX_EXECUTION_DATE='2024-11-17T23:23:03.350557+00:00' AIRFLOW_CTX_TRY_NUMBER='2' AIRFLOW_CTX_DAG_RUN_ID='manual__2024-11-17T23:23:03.350557+00:00'
[2024-11-17T23:23:16.404+0000] {logging_mixin.py:190} INFO - Task instance is in running state
[2024-11-17T23:23:16.405+0000] {logging_mixin.py:190} INFO -  Previous state of the Task instance: queued
[2024-11-17T23:23:16.405+0000] {logging_mixin.py:190} INFO - Current task name:insert_sales_data state:running start_date:2024-11-17 23:23:16.083628+00:00
[2024-11-17T23:23:16.406+0000] {logging_mixin.py:190} INFO - Dag name:raw_api_sales_data and current dag run status:running
[2024-11-17T23:23:16.406+0000] {taskinstance.py:731} INFO - ::endgroup::
[2024-11-17T23:23:16.415+0000] {logging_mixin.py:190} INFO - sales_data: [{'customer_id': 683, 'customer_name': 'Laney Rabb', 'age': 38, 'email': 'lrabb0@msn.com', 'country': 'Ukraine', 'postal_code': nan, 'purchase_id': 1770, 'purchase_quantity': 81, 'purchase_date': '4/30/2021', 'product_id': 2031, 'product_name': 'Wine La Vielle Ferme Cote Du', 'quantity': 941, 'total_price': 692.87, 'price_unit': 289.91}, {'customer_id': 387, 'customer_name': 'Analiese Kennady', 'age': 76, 'email': 'akennady1@mozilla.com', 'country': 'Colombia', 'postal_code': '503068', 'purchase_id': 1408, 'purchase_quantity': 42, 'purchase_date': '2/13/2021', 'product_id': 2089, 'product_name': 'Wasabi Powder', 'quantity': 201, 'total_price': 6571.05, 'price_unit': 613.32}, {'customer_id': 213, 'customer_name': 'Archambault Kornilyev', 'age': 47, 'email': 'akornilyev2@state.tx.us', 'country': 'Thailand', 'postal_code': '15130', 'purchase_id': 802, 'purchase_quantity': 37, 'purchase_date': '4/16/2021', 'product_id': 2088, 'product_name': 'Melon - Cantaloupe', 'quantity': 249, 'total_price': 879.27, 'price_unit': 848.49}, {'customer_id': 511, 'customer_name': 'Nanny Stealey', 'age': 70, 'email': 'nstealey3@paginegialle.it', 'country': 'Poland', 'postal_code': '85-980', 'purchase_id': 647, 'purchase_quantity': 11, 'purchase_date': '4/19/2021', 'product_id': 2001, 'product_name': 'Cheese - Parmigiano Reggiano', 'quantity': 861, 'total_price': 8721.98, 'price_unit': 695.31}, {'customer_id': 235, 'customer_name': 'Barbi Gyde', 'age': 68, 'email': 'bgyde4@booking.com', 'country': 'Sweden', 'postal_code': '832 93', 'purchase_id': 580, 'purchase_quantity': 1, 'purchase_date': '10/24/2021', 'product_id': 2097, 'product_name': 'Mint - Fresh', 'quantity': 218, 'total_price': 6814.09, 'price_unit': 394.35}, {'customer_id': 228, 'customer_name': 'Bettine Yearne', 'age': 65, 'email': 'byearne5@printfriendly.com', 'country': 'China', 'postal_code': nan, 'purchase_id': 1706, 'purchase_quantity': 51, 'purchase_date': '4/2/2021', 'product_id': 2034, 'product_name': 'Sachet', 'quantity': 381, 'total_price': 3996.58, 'price_unit': 419.83}, {'customer_id': 182, 'customer_name': 'Derwin Lound', 'age': 55, 'email': 'dlound6@hp.com', 'country': 'Indonesia', 'postal_code': nan, 'purchase_id': 865, 'purchase_quantity': 82, 'purchase_date': '3/16/2021', 'product_id': 2086, 'product_name': 'Salad Dressing', 'quantity': 131, 'total_price': 3066.86, 'price_unit': 801.48}, {'customer_id': 62, 'customer_name': 'Tiphani Coslett', 'age': 53, 'email': 'tcoslett7@vistaprint.com', 'country': 'China', 'postal_code': nan, 'purchase_id': 1471, 'purchase_quantity': 22, 'purchase_date': '11/21/2021', 'product_id': 2061, 'product_name': 'Sauce - Thousand Island', 'quantity': 442, 'total_price': 8554.62, 'price_unit': 730.87}, {'customer_id': 345, 'customer_name': 'Boniface Abate', 'age': 52, 'email': 'babate8@mapy.cz', 'country': 'Indonesia', 'postal_code': nan, 'purchase_id': 487, 'purchase_quantity': 87, 'purchase_date': '4/23/2021', 'product_id': 2059, 'product_name': 'Vinegar - Rice', 'quantity': 211, 'total_price': 846.59, 'price_unit': 216.17}, {'customer_id': 138, 'customer_name': 'Kristos Asipenko', 'age': 47, 'email': 'kasipenko9@nbcnews.com', 'country': 'Egypt', 'postal_code': nan, 'purchase_id': 729, 'purchase_quantity': 82, 'purchase_date': '1/11/2021', 'product_id': 2062, 'product_name': 'Lamb Shoulder Boneless Nz', 'quantity': 492, 'total_price': 5190.87, 'price_unit': 980.68}]
[2024-11-17T23:23:16.423+0000] {base.py:84} INFO - Retrieving connection 'postgres_default'
[2024-11-17T23:23:16.425+0000] {taskinstance.py:3311} ERROR - Task failed with exception
Traceback (most recent call last):
  File "/home/airflow/.local/lib/python3.12/site-packages/airflow/models/taskinstance.py", line 767, in _execute_task
    result = _execute_callable(context=context, **execute_callable_kwargs)
             ^^^^^^^^^^^^^^^^^^^^^^^^^^^^^^^^^^^^^^^^^^^^^^^^^^^^^^^^^^^^^
  File "/home/airflow/.local/lib/python3.12/site-packages/airflow/models/taskinstance.py", line 733, in _execute_callable
    return ExecutionCallableRunner(
           ^^^^^^^^^^^^^^^^^^^^^^^^
  File "/home/airflow/.local/lib/python3.12/site-packages/airflow/utils/operator_helpers.py", line 252, in run
    return self.func(*args, **kwargs)
           ^^^^^^^^^^^^^^^^^^^^^^^^^^
  File "/home/airflow/.local/lib/python3.12/site-packages/airflow/models/baseoperator.py", line 417, in wrapper
    return func(self, *args, **kwargs)
           ^^^^^^^^^^^^^^^^^^^^^^^^^^^
  File "/home/airflow/.local/lib/python3.12/site-packages/airflow/operators/python.py", line 238, in execute
    return_value = self.execute_callable()
                   ^^^^^^^^^^^^^^^^^^^^^^^
  File "/home/airflow/.local/lib/python3.12/site-packages/airflow/operators/python.py", line 256, in execute_callable
    return runner.run(*self.op_args, **self.op_kwargs)
           ^^^^^^^^^^^^^^^^^^^^^^^^^^^^^^^^^^^^^^^^^^^
  File "/home/airflow/.local/lib/python3.12/site-packages/airflow/utils/operator_helpers.py", line 252, in run
    return self.func(*args, **kwargs)
           ^^^^^^^^^^^^^^^^^^^^^^^^^^
  File "/opt/airflow/dags/fetch_data.py", line 61, in insert_sales_data
    conn = hook.get_conn()
           ^^^^^^^^^^^^^^^
  File "/home/airflow/.local/lib/python3.12/site-packages/airflow/providers/postgres/hooks/postgres.py", line 181, in get_conn
    self.conn = psycopg2.connect(**conn_args)
                ^^^^^^^^^^^^^^^^^^^^^^^^^^^^^
  File "/home/airflow/.local/lib/python3.12/site-packages/psycopg2/__init__.py", line 122, in connect
    conn = _connect(dsn, connection_factory=connection_factory, **kwasync)
           ^^^^^^^^^^^^^^^^^^^^^^^^^^^^^^^^^^^^^^^^^^^^^^^^^^^^^^^^^^^^^^^
psycopg2.OperationalError: connection to server at "localhost" (::1), port 5432 failed: Connection refused
	Is the server running on that host and accepting TCP/IP connections?
connection to server at "localhost" (127.0.0.1), port 5432 failed: Connection refused
	Is the server running on that host and accepting TCP/IP connections?

[2024-11-17T23:23:16.437+0000] {logging_mixin.py:190} INFO - Task instance in failure state
[2024-11-17T23:23:16.438+0000] {logging_mixin.py:190} INFO - Task start:2024-11-17 23:23:16.083628+00:00 end:2024-11-17 23:23:16.437566+00:00 duration:0.353938
[2024-11-17T23:23:16.439+0000] {logging_mixin.py:190} INFO - Task:<Task(PythonOperator): insert_sales_data> dag:<DAG: raw_api_sales_data> dagrun:<DagRun raw_api_sales_data @ 2024-11-17 23:23:03.350557+00:00: manual__2024-11-17T23:23:03.350557+00:00, state:running, queued_at: 2024-11-17 23:23:03.359974+00:00. externally triggered: True>
[2024-11-17T23:23:16.439+0000] {logging_mixin.py:190} INFO - Failure caused by connection to server at "localhost" (::1), port 5432 failed: Connection refused
	Is the server running on that host and accepting TCP/IP connections?
connection to server at "localhost" (127.0.0.1), port 5432 failed: Connection refused
	Is the server running on that host and accepting TCP/IP connections?
[2024-11-17T23:23:16.440+0000] {taskinstance.py:1225} INFO - Marking task as FAILED. dag_id=raw_api_sales_data, task_id=insert_sales_data, run_id=manual__2024-11-17T23:23:03.350557+00:00, execution_date=20241117T232303, start_date=20241117T232316, end_date=20241117T232316
[2024-11-17T23:23:16.452+0000] {taskinstance.py:340} INFO - ::group::Post task execution logs
[2024-11-17T23:23:16.452+0000] {standard_task_runner.py:124} ERROR - Failed to execute job 166 for task insert_sales_data (connection to server at "localhost" (::1), port 5432 failed: Connection refused
	Is the server running on that host and accepting TCP/IP connections?
connection to server at "localhost" (127.0.0.1), port 5432 failed: Connection refused
	Is the server running on that host and accepting TCP/IP connections?
; 976)
Traceback (most recent call last):
  File "/home/airflow/.local/lib/python3.12/site-packages/airflow/task/task_runner/standard_task_runner.py", line 117, in _start_by_fork
    ret = args.func(args, dag=self.dag)
          ^^^^^^^^^^^^^^^^^^^^^^^^^^^^^
  File "/home/airflow/.local/lib/python3.12/site-packages/airflow/cli/cli_config.py", line 49, in command
    return func(*args, **kwargs)
           ^^^^^^^^^^^^^^^^^^^^^
  File "/home/airflow/.local/lib/python3.12/site-packages/airflow/utils/cli.py", line 116, in wrapper
    return f(*args, **kwargs)
           ^^^^^^^^^^^^^^^^^^
  File "/home/airflow/.local/lib/python3.12/site-packages/airflow/cli/commands/task_command.py", line 483, in task_run
    task_return_code = _run_task_by_selected_method(args, _dag, ti)
                       ^^^^^^^^^^^^^^^^^^^^^^^^^^^^^^^^^^^^^^^^^^^^
  File "/home/airflow/.local/lib/python3.12/site-packages/airflow/cli/commands/task_command.py", line 256, in _run_task_by_selected_method
    return _run_raw_task(args, ti)
           ^^^^^^^^^^^^^^^^^^^^^^^
  File "/home/airflow/.local/lib/python3.12/site-packages/airflow/cli/commands/task_command.py", line 341, in _run_raw_task
    return ti._run_raw_task(
           ^^^^^^^^^^^^^^^^^
  File "/home/airflow/.local/lib/python3.12/site-packages/airflow/utils/session.py", line 97, in wrapper
    return func(*args, session=session, **kwargs)
           ^^^^^^^^^^^^^^^^^^^^^^^^^^^^^^^^^^^^^^
  File "/home/airflow/.local/lib/python3.12/site-packages/airflow/models/taskinstance.py", line 3005, in _run_raw_task
    return _run_raw_task(
           ^^^^^^^^^^^^^^
  File "/home/airflow/.local/lib/python3.12/site-packages/airflow/models/taskinstance.py", line 273, in _run_raw_task
    TaskInstance._execute_task_with_callbacks(
  File "/home/airflow/.local/lib/python3.12/site-packages/airflow/models/taskinstance.py", line 3159, in _execute_task_with_callbacks
    result = self._execute_task(context, task_orig)
             ^^^^^^^^^^^^^^^^^^^^^^^^^^^^^^^^^^^^^^
  File "/home/airflow/.local/lib/python3.12/site-packages/airflow/models/taskinstance.py", line 3183, in _execute_task
    return _execute_task(self, context, task_orig)
           ^^^^^^^^^^^^^^^^^^^^^^^^^^^^^^^^^^^^^^^
  File "/home/airflow/.local/lib/python3.12/site-packages/airflow/models/taskinstance.py", line 767, in _execute_task
    result = _execute_callable(context=context, **execute_callable_kwargs)
             ^^^^^^^^^^^^^^^^^^^^^^^^^^^^^^^^^^^^^^^^^^^^^^^^^^^^^^^^^^^^^
  File "/home/airflow/.local/lib/python3.12/site-packages/airflow/models/taskinstance.py", line 733, in _execute_callable
    return ExecutionCallableRunner(
           ^^^^^^^^^^^^^^^^^^^^^^^^
  File "/home/airflow/.local/lib/python3.12/site-packages/airflow/utils/operator_helpers.py", line 252, in run
    return self.func(*args, **kwargs)
           ^^^^^^^^^^^^^^^^^^^^^^^^^^
  File "/home/airflow/.local/lib/python3.12/site-packages/airflow/models/baseoperator.py", line 417, in wrapper
    return func(self, *args, **kwargs)
           ^^^^^^^^^^^^^^^^^^^^^^^^^^^
  File "/home/airflow/.local/lib/python3.12/site-packages/airflow/operators/python.py", line 238, in execute
    return_value = self.execute_callable()
                   ^^^^^^^^^^^^^^^^^^^^^^^
  File "/home/airflow/.local/lib/python3.12/site-packages/airflow/operators/python.py", line 256, in execute_callable
    return runner.run(*self.op_args, **self.op_kwargs)
           ^^^^^^^^^^^^^^^^^^^^^^^^^^^^^^^^^^^^^^^^^^^
  File "/home/airflow/.local/lib/python3.12/site-packages/airflow/utils/operator_helpers.py", line 252, in run
    return self.func(*args, **kwargs)
           ^^^^^^^^^^^^^^^^^^^^^^^^^^
  File "/opt/airflow/dags/fetch_data.py", line 61, in insert_sales_data
    conn = hook.get_conn()
           ^^^^^^^^^^^^^^^
  File "/home/airflow/.local/lib/python3.12/site-packages/airflow/providers/postgres/hooks/postgres.py", line 181, in get_conn
    self.conn = psycopg2.connect(**conn_args)
                ^^^^^^^^^^^^^^^^^^^^^^^^^^^^^
  File "/home/airflow/.local/lib/python3.12/site-packages/psycopg2/__init__.py", line 122, in connect
    conn = _connect(dsn, connection_factory=connection_factory, **kwasync)
           ^^^^^^^^^^^^^^^^^^^^^^^^^^^^^^^^^^^^^^^^^^^^^^^^^^^^^^^^^^^^^^^
psycopg2.OperationalError: connection to server at "localhost" (::1), port 5432 failed: Connection refused
	Is the server running on that host and accepting TCP/IP connections?
connection to server at "localhost" (127.0.0.1), port 5432 failed: Connection refused
	Is the server running on that host and accepting TCP/IP connections?

[2024-11-17T23:23:16.485+0000] {local_task_job_runner.py:266} INFO - Task exited with return code 1
[2024-11-17T23:23:16.501+0000] {taskinstance.py:3895} INFO - 0 downstream tasks scheduled from follow-on schedule check
[2024-11-17T23:23:16.504+0000] {local_task_job_runner.py:245} INFO - ::endgroup::
